Workbook

Sheet COSTINGMODEL
A1: COURIER | B1: ACTUAL WEIGHT SLAB IN KG | C1: VOLUMETRIC WEIGHT | F1: VOL. WEIGHT | G1: BILLABLE WEIGHT | H1: DESTINATION | I1: WEIGHT SLAB | J1: FREIGHT RATES | K1: FUEL SURCHARGE | L1: LANDED COST | M1: GST 18% EXTRA | N1: TOTAL COST
C2: L | D2: B | E2: H
A3: SHREE MARUTI COURIER SERVICE | B3: 4.5 | C3: 50 | D3: 41 | E3: 70 | F3: =($C$3*$D$3*$E$3)/5000 -> 28.7 | G3: =MAX($B$3, $F$3) -> 28.7 | H3: WITHIN ZONE | I3: 30 | J3: =INDEX(INDIRECT("'"&A3&"'!B:G"), MATCH(I3, INDIRECT("'"&A3&"'!A:A"), 0), MATCH(H3, INDIRECT("'"&A3&"'!B1:G1"), 0)) -> 1500 | K3: =J3*_xlfn.XLOOKUP(A3,$A$7:$A$11,$B$7:$B$11) -> 150 | L3: =SUM(J3, K3) -> 1650 | M3: =L3*18% -> 297 | N3: =SUM(L3, M3) -> 1947
A6: COURIER | B6: FUEL %
A7: PROFESSIONAL COURIER SERVICE | B7: 0.1
A8: ANJANI COURIER SERVICE | B8: 0.35
A9: SHREE MARUTI COURIER SERVICE | B9: 0.1
A10: DTDC | B10: 0.1
A11: ITHINK LOGISTIC SHADOWFAX | B11: 0.1

Sheet COMPARATIVE
A1: DOMESTIC COURIER CHARGE
A2: WITHIN CITY | O2: WITHIN STATE | AA2: WITHIN ZONE | AM2: METRO TO METRO | AZ2: REST OF INDIA | BM2: SPECIAL DESTINATION
A3: NON-DOCUMENT CHARGE BY SURFACE | O3: NON-DOCUMENT CHARGE BY SURFACE | AA3: NON-DOCUMENT CHARGE BY SURFACE | AM3: NON-DOCUMENT CHARGE BY SURFACE | AZ3: NON-DOCUMENT CHARGE BY SURFACE | BM3: NON-DOCUMENT CHARGE BY SURFACE
A4: SR.NO. | B4: KGS | C4: PROFESSIONAL COURIER SERVICE | D4: TOTAL COST | E4: DTDC | F4: TOTAL COST | G4: SHREE MARUTI COURIER SERVICE | H4: TOTAL COST | I4: ITHINK SHADOWFAX | J4: DIFF. | K4: %DIFF. SHREE MARUTI VS PROFF | L4: %DIFF DTDC VS ITHINK SHADOWFAX | M4: %DIFF DTDC VS SHREE MARUTI | O4: KGS | P4: PROFESSIONAL COURIER SERVICE | Q4: TOTAL COST | R4: DTDC | S4: TOTAL COST | T4: SHREE MARUTI COURIER SERVICE | U4: TOTAL COST | V4: ITHINK SHADOWFAX | W4: DIFF. | X4: %DIFF.DTDC VS SHREE MARUTI | Y4: %DIFF.DTDC VS ITHINK | AA4: KGS | AB4: PROFESSIONAL COURIER SERVICE | AC4: TOTAL COST | AD4: DTDC | AE4: TOTAL COST | AF4: SHREE MARUTI COURIER SERVICE | AG4: TOTAL COST | AH4: ITHINK SHADOWFAX | AI4: DIFF. | AJ4: %DIFF DTDC VS SHREE MARUTI. | AK4: %DIFF DTDC VS ITHINK | AM4: KGS | AN4: PROFESSIONAL COURIER SERVICE | AO4: TOTAL COST | AP4: DTDC | AQ4: TOTAL COST | AR4: SHREE MARUTI COURIER SERVICE | AS4: TOTAL COST | AT4: ITHINK SHADOWFAX | AU4: DIFF. | AV4: %DIFF. PROFESS VS SHREE MARUTI | AW4: %DIFF DTDC VS SHREE MARUTI | AX4: DTDC VS ITHINK | AZ4: KGS | BA4: PROFESSIONAL COURIER SERVICE | BB4: TOTAL COST | BC4: DTDC | BD4: TOTAL COST | BE4: SHREE MARUTI COURIER SERVICE | BF4: TOTAL COST | BG4: ITHINK | BH4: DIFF. | BI4: %DIFF. PROFESS VS SHREE MARUTI | BJ4: DTDC VS ITHINK | BK4: %DIFF DTDC VS SHREE MARUTI | BM4: KGS | BN4: PROFESSIONAL COURIER SERVICE | BO4: TOTAL COST | BP4: DTDC | BQ4: TOTAL COST | BR4: SHREE MARUTI COURIER SERVICE | BS4: TOTAL COST | BT4: ITHINK | BU4: DIFF. | BV4: %DIFF. PROFESS VS SHREE MARUTI | BW4: %DIFF DTDC VS SHREE MARUTI
A5: {=_xlfn.SEQUENCE(50)} -> 1 | B5: 1 | C5: {=VLOOKUP(B5:B54, WITHINCITY!B4:C105,2,0)} -> 15 | D5: {=VLOOKUP(B5:B54, WITHINCITY!B4:N53,13,0)} -> 16.5 | E5: {=VLOOKUP(B5:B54, WITHINCITY!B4:E105,4,0)} -> 54 | F5: {=VLOOKUP(B5:B54, WITHINCITY!B4:P53,15,0)} -> 59.4 | G5: {=VLOOKUP(B5:B54, WITHINCITY!B4:F105,5,0)} -> 15 | H5: {=VLOOKUP(B5:B54, WITHINCITY!B4:Q53,16,0)} -> 16.5 | I5: {=VLOOKUP(B5:B54, WITHINCITY!B4:J53,9,0)} -> 54 | J5: =MAX(D5, F5, H5) - MIN(D5, F5, H5) -> 42.9 | K5: =J5/MIN(D5, F5, H5) -> 2.6 | O5: 1 | P5: {=VLOOKUP(O5:O54, WITHINSTATE!B4:C105,2,0)} -> 35 | Q5: {=VLOOKUP(O5:O54, WITHINSTATE!B4:N53,13,0)} -> 38.5 | R5: {=VLOOKUP(O5:O54, WITHINSTATE!B4:E105,4,0)} -> 60 | S5: {=VLOOKUP(O5:O54, WITHINSTATE!B4:P53,15,0)} -> 66 | T5: {=VLOOKUP(O5:O54, WITHINSTATE!B4:F53,5,0)} -> 25 | U5: {=VLOOKUP(O5:O54, WITHINSTATE!B4:Q53,16,0)} -> 27.5 | V5: {=VLOOKUP(O5:O54, WITHINSTATE!B4:J53,9,0)} -> 59 | W5: =MAX(Q5, S5, U5) - MIN(Q5, S5, U5) -> 38.5 | AA5: 1 | AB5: {=VLOOKUP(AA5:AA54, WITHINZONE!B4:C105,2,0)} -> 40 | AC5: {=VLOOKUP(AA5:AA54, WITHINZONE!B4:N53,13,0)} -> 44 | AD5: {=VLOOKUP(AA5:AA54, WITHINZONE!B4:E53,4,0)} -> 75 | AE5: {=VLOOKUP(AA5:AA54, WITHINZONE!B4:P53,15,0)} -> 82.5 | AF5: {=VLOOKUP(AA5:AA54, WITHINZONE!B4:F53,5,0)} -> 50 | AG5: {=VLOOKUP(AA5:AA54, WITHINZONE!B4:Q53,16,0)} -> 55 | AH5: {=VLOOKUP(AA5:AA54, WITHINZONE!B4:J53,9,0)} -> 59 | AI5: =MAX(AC5, AE5, AG5) - MIN(AC5, AE5, AG5) -> 38.5 | AM5: 1 | AN5: {=VLOOKUP(AM5:AM54, 'METRO TO METRO'!B4:C105,2,0)} -> 70 | AO5: {=VLOOKUP(AM5:AM54, 'METRO TO METRO'!B4:N53,13,0)} -> 77 | AP5: {=VLOOKUP(AM5:AM54, 'METRO TO METRO'!B4:E53,4,0)} -> 84 | AQ5: {=VLOOKUP(AM5:AM54, 'METRO TO METRO'!B4:P53,15,0)} -> 92.4 | AR5: {=VLOOKUP(AM5:AM54, 'METRO TO METRO'!B4:F53,5,0)} -> 55 | AS5: {=VLOOKUP(AM5:AM54, 'METRO TO METRO'!B4:Q53,16,0)} -> 60.5 | AT5: {=VLOOKUP(AM5:AM54, 'METRO TO METRO'!B4:J53,9,0)} -> 71.25 | AU5: =MAX(AO5, AQ5, AS5) - MIN(AO5, AQ5, AS5) -> 31.9 | AV5: =AU5/MIN(AO5, AQ5, AS5) -> 0.52727273 | AZ5: 1 | BA5: {=VLOOKUP(AZ5:AZ54, RESTOFINDIA!B4:C53,2,0)} -> 70 | BB5: {=VLOOKUP(AZ5:AZ54, RESTOFINDIA!B4:N53,13,0)} -> 77 | BC5: {=VLOOKUP(AZ5:AZ54, RESTOFINDIA!B4:E53,4,0)} -> 90 | BD5: {=VLOOKUP(AZ5:AZ54, RESTOFINDIA!B4:P53,15,0)} -> 99 | BE5: {=VLOOKUP(AZ5:AZ54, RESTOFINDIA!B4:F53,5,0)} -> 50 | BF5: {=VLOOKUP(AZ5:AZ54, RESTOFINDIA!B4:Q53,16,0)} -> 55 | BG5: {=VLOOKUP(AZ5:AZ54, RESTOFINDIA!B4:J53,9,0)} -> 75.25 | BH5: =MAX(BB5, BD5, BF5) - MIN(BB5, BD5, BF5) -> 44 | BI5: =BH5/MIN(BB5, BD5, BF5) -> 0.8 | BM5: 1 | BN5: {=VLOOKUP(BM5:BM54, SPECIALDESTINATION!B4:C53,2,0)} -> 70 | BO5: {=VLOOKUP(BM5:BM54, SPECIALDESTINATION!B4:N53,13,0)} -> 77 | BP5: {=VLOOKUP(BM5:BM54, SPECIALDESTINATION!B4:E53,4,0)} -> 135 | BQ5: {=VLOOKUP(BM5:BM54, SPECIALDESTINATION!B4:O53,14,0)} -> 148.5 | BR5: {=VLOOKUP(BM5:BM54, SPECIALDESTINATION!B4:F53,5,0)} -> 60 | BS5: {=VLOOKUP(BM5:BM54, SPECIALDESTINATION!B4:P53,15,0)} -> 66 | BT5: {=VLOOKUP(BM5:BM54, SPECIALDESTINATION!B4:J53,9,0)} -> 90.25 | BU5: =MAX(BO5, BQ5, BS5) - MIN(BO5, BQ5, BS5) -> 82.5 | BV5: =BU5/MIN(BO5, BQ5, BS5) -> 1.25
A6: 2 | B6: =B5 + 1 -> 2 | C6: 30 | D6: 33 | E6: 54 | F6: 59.4 | G6: 30 | H6: 33 | I6: 105.5 | J6: =MAX(D6, F6, H6) - MIN(D6, F6, H6) -> 26.4 | K6: =J6/MIN(D6, F6, H6) -> 0.8 | O6: =O5 + 1 -> 2 | P6: 70 | Q6: 77 | R6: 60 | S6: 66 | T6: 50 | U6: 55 | V6: 115.5 | W6: =MAX(Q6, S6, U6) - MIN(Q6, S6, U6) -> 22 | AA6: =AA5 + 1 -> 2 | AB6: 80 | AC6: 88 | AD6: 75 | AE6: 82.5 | AF6: 100 | AG6: 110 | AH6: 115.5 | AI6: =MAX(AC6, AE6, AG6) - MIN(AC6, AE6, AG6) -> 27.5 | AM6: =AM5 + 1 -> 2 | AN6: 140 | AO6: 154 | AP6: 84 | AQ6: 92.4 | AR6: 110 | AS6: 121 | AT6: 138.75 | AU6: =MAX(AO6, AQ6, AS6) - MIN(AO6, AQ6, AS6) -> 61.6 | AV6: =AU6/MIN(AO6, AQ6, AS6) -> 0.66666667 | AZ6: =AZ5 + 1 -> 2 | BA6: 140 | BB6: 154 | BC6: 90 | BD6: 99 | BE6: 100 | BF6: 110 | BG6: 146.75 | BH6: =MAX(BB6, BD6, BF6) - MIN(BB6, BD6, BF6) -> 55 | BI6: =BH6/MIN(BB6, BD6, BF6) -> 0.55555556 | BM6: =BM5 + 1 -> 2 | BN6: 140 | BO6: 154 | BP6: 135 | BQ6: 148.5 | BR6: 120 | BS6: 132 | BT6: 176.75 | BU6: =MAX(BO6, BQ6, BS6) - MIN(BO6, BQ6, BS6) -> 22 | BV6: =BU6/MIN(BO6, BQ6, BS6) -> 0.16666667
A7: 3 | B7: =B6 + 1 -> 3 | C7: 45 | D7: 49.5 | E7: 54 | F7: 59.4 | G7: 45 | H7: 49.5 | I7: 157 | J7: =MAX(D7, F7, H7) - MIN(D7, F7, H7) -> 9.9 | K7: =J7/MIN(D7, F7, H7) -> 0.2 | L7: =(F7-I7)/F7 -> -1.6430976 | M7: =(F7-H7)/F7 -> 0.16666667 | O7: =O6 + 1 -> 3 | P7: 105 | Q7: 115.5 | R7: 60 | S7: 66 | T7: 75 | U7: 82.5 | V7: 172 | W7: =MAX(Q7, S7, U7) - MIN(Q7, S7, U7) -> 49.5 | X7: =(R7-T7)/R7 -> -0.25 | Y7: =(S7-V7)/S7 -> -1.6060606 | AA7: =AA6 + 1 -> 3 | AB7: 120 | AC7: 132 | AD7: 75 | AE7: 82.5 | AF7: 150 | AG7: 165 | AH7: 172 | AI7: =MAX(AC7, AE7, AG7) - MIN(AC7, AE7, AG7) -> 82.5 | AJ7: =(AE7-AG7)/AG7 -> -0.5 | AK7: =(AE7-AH7)/AH7 -> -0.52034884 | AM7: =AM6 + 1 -> 3 | AN7: 210 | AO7: 231 | AP7: 84 | AQ7: 92.4 | AR7: 165 | AS7: 181.5 | AT7: 206.25 | AU7: =MAX(AO7, AQ7, AS7) - MIN(AO7, AQ7, AS7) -> 138.6 | AV7: =AU7/MIN(AO7, AQ7, AS7) -> 1.5 | AW7: =(AP7-AR7)/AR7 -> -0.49090909 | AX7: =(AQ7-AT7)/AT7 -> -0.552 | AZ7: =AZ6 + 1 -> 3 | BA7: 210 | BB7: 231 | BC7: 90 | BD7: 99 | BE7: 150 | BF7: 165 | BG7: 218.25 | BH7: =MAX(BB7, BD7, BF7) - MIN(BB7, BD7, BF7) -> 132 | BI7: =BH7/MIN(BB7, BD7, BF7) -> 1.3333333 | BJ7: =(BD7-BG7)/BG7 -> -0.54639175 | BK7: =(BC7-BE7)/BE7 -> -0.4 | BM7: =BM6 + 1 -> 3 | BN7: 210 | BO7: 231 | BP7: 135 | BQ7: 148.5 | BR7: 180 | BS7: 198 | BT7: 263.25 | BU7: =MAX(BO7, BQ7, BS7) - MIN(BO7, BQ7, BS7) -> 82.5 | BV7: =BU7/MIN(BO7, BQ7, BS7) -> 0.55555556 | BW7: =(BP7-BR7)/BR7 -> -0.25
A8: 4 | B8: =B7 + 1 -> 4 | C8: 60 | D8: 66 | E8: 72 | F8: 79.2 | G8: 60 | H8: 66 | I8: 208.5 | J8: =MAX(D8, F8, H8) - MIN(D8, F8, H8) -> 13.2 | K8: =J8/MIN(D8, F8, H8) -> 0.2 | L8: =(F8-I8)/F8 -> -1.6325758 | M8: =(F8-H8)/F8 -> 0.16666667 | O8: =O7 + 1 -> 4 | P8: 140 | Q8: 154 | R8: 80 | S8: 88 | T8: 100 | U8: 110 | V8: 228.5 | W8: =MAX(Q8, S8, U8) - MIN(Q8, S8, U8) -> 66 | X8: =(R8-T8)/R8 -> -0.25 | Y8: =(S8-V8)/S8 -> -1.5965909 | AA8: =AA7 + 1 -> 4 | AB8: 160 | AC8: 176 | AD8: 100 | AE8: 110 | AF8: 200 | AG8: 220 | AH8: 228.5 | AI8: =MAX(AC8, AE8, AG8) - MIN(AC8, AE8, AG8) -> 110 | AJ8: =(AE8-AG8)/AG8 -> -0.5 | AK8: =(AE8-AH8)/AH8 -> -0.51859956 | AM8: =AM7 + 1 -> 4 | AN8: 280 | AO8: 308 | AP8: 112 | AQ8: 123.2 | AR8: 220 | AS8: 242 | AT8: 273.75 | AU8: =MAX(AO8, AQ8, AS8) - MIN(AO8, AQ8, AS8) -> 184.8 | AV8: =AU8/MIN(AO8, AQ8, AS8) -> 1.5 | AW8: =(AP8-AR8)/AR8 -> -0.49090909 | AX8: =(AQ8-AT8)/AT8 -> -0.54995434 | AZ8: =AZ7 + 1 -> 4 | BA8: 280 | BB8: 308 | BC8: 120 | BD8: 132 | BE8: 200 | BF8: 220 | BG8: 289.75 | BH8: =MAX(BB8, BD8, BF8) - MIN(BB8, BD8, BF8) -> 176 | BI8: =BH8/MIN(BB8, BD8, BF8) -> 1.3333333 | BJ8: =(BD8-BG8)/BG8 -> -0.54443486 | BK8: =(BC8-BE8)/BE8 -> -0.4 | BM8: =BM7 + 1 -> 4 | BN8: 280 | BO8: 308 | BP8: 180 | BQ8: 198 | BR8: 240 | BS8: 264 | BT8: 349.75 | BU8: =MAX(BO8, BQ8, BS8) - MIN(BO8, BQ8, BS8) -> 110 | BV8: =BU8/MIN(BO8, BQ8, BS8) -> 0.55555556 | BW8: =(BP8-BR8)/BR8 -> -0.25
A9: 5 | B9: =B8 + 1 -> 5 | C9: 75 | D9: 82.5 | E9: 90 | F9: 99 | G9: 75 | H9: 82.5 | I9: 260 | J9: =MAX(D9, F9, H9) - MIN(D9, F9, H9) -> 16.5 | K9: =J9/MIN(D9, F9, H9) -> 0.2 | L9: =(F9-I9)/F9 -> -1.6262626 | M9: =(F9-H9)/F9 -> 0.16666667 | O9: =O8 + 1 -> 5 | P9: 175 | Q9: 192.5 | R9: 100 | S9: 110 | T9: 125 | U9: 137.5 | V9: 285 | W9: =MAX(Q9, S9, U9) - MIN(Q9, S9, U9) -> 82.5 | X9: =(R9-T9)/R9 -> -0.25 | Y9: =(S9-V9)/S9 -> -1.5909091 | AA9: =AA8 + 1 -> 5 | AB9: 200 | AC9: 220 | AD9: 125 | AE9: 137.5 | AF9: 250 | AG9: 275 | AH9: 285 | AI9: =MAX(AC9, AE9, AG9) - MIN(AC9, AE9, AG9) -> 137.5 | AJ9: =(AE9-AG9)/AG9 -> -0.5 | AK9: =(AE9-AH9)/AH9 -> -0.51754386 | AM9: =AM8 + 1 -> 5 | AN9: 350 | AO9: 385 | AP9: 140 | AQ9: 154 | AR9: 275 | AS9: 302.5 | AT9: 341.25 | AU9: =MAX(AO9, AQ9, AS9) - MIN(AO9, AQ9, AS9) -> 231 | AV9: =AU9/MIN(AO9, AQ9, AS9) -> 1.5 | AW9: =(AP9-AR9)/AR9 -> -0.49090909 | AX9: =(AQ9-AT9)/AT9 -> -0.54871795 | AZ9: =AZ8 + 1 -> 5 | BA9: 350 | BB9: 385 | BC9: 150 | BD9: 165 | BE9: 250 | BF9: 275 | BG9: 361.25 | BH9: =MAX(BB9, BD9, BF9) - MIN(BB9, BD9, BF9) -> 220 | BI9: =BH9/MIN(BB9, BD9, BF9) -> 1.3333333 | BJ9: =(BD9-BG9)/BG9 -> -0.5432526 | BK9: =(BC9-BE9)/BE9 -> -0.4 | BM9: =BM8 + 1 -> 5 | BN9: 350 | BO9: 385 | BP9: 225 | BQ9: 247.5 | BR9: 300 | BS9: 330 | BT9: 436.25 | BU9: =MAX(BO9, BQ9, BS9) - MIN(BO9, BQ9, BS9) -> 137.5 | BV9: =BU9/MIN(BO9, BQ9, BS9) -> 0.55555556 | BW9: =(BP9-BR9)/BR9 -> -0.25
A10: 6 | B10: =B9 + 1 -> 6 | C10: 90 | D10: 99 | E10: 108 | F10: 118.8 | G10: 90 | H10: 99 | I10: 311.5 | J10: =MAX(D10, F10, H10) - MIN(D10, F10, H10) -> 19.8 | K10: =J10/MIN(D10, F10, H10) -> 0.2 | L10: =(F10-I10)/F10 -> -1.6220539 | M10: =(F10-H10)/F10 -> 0.16666667 | O10: =O9 + 1 -> 6 | P10: 210 | Q10: 231 | R10: 120 | S10: 132 | T10: 150 | U10: 165 | V10: 341.5 | W10: =MAX(Q10, S10, U10) - MIN(Q10, S10, U10) -> 99 | X10: =(R10-T10)/R10 -> -0.25 | Y10: =(S10-V10)/S10 -> -1.5871212 | AA10: =AA9 + 1 -> 6 | AB10: 240 | AC10: 264 | AD10: 150 | AE10: 165 | AF10: 300 | AG10: 330 | AH10: 341.5 | AI10: =MAX(AC10, AE10, AG10) - MIN(AC10, AE10, AG10) -> 165 | AJ10: =(AE10-AG10)/AG10 -> -0.5 | AK10: =(AE10-AH10)/AH10 -> -0.51683748 | AM10: =AM9 + 1 -> 6 | AN10: 420 | AO10: 462 | AP10: 168 | AQ10: 184.8 | AR10: 330 | AS10: 363 | AT10: 408.75 | AU10: =MAX(AO10, AQ10, AS10) - MIN(AO10, AQ10, AS10) -> 277.2 | AV10: =AU10/MIN(AO10, AQ10, AS10) -> 1.5 | AW10: =(AP10-AR10)/AR10 -> -0.49090909 | AX10: =(AQ10-AT10)/AT10 -> -0.54788991 | AZ10: =AZ9 + 1 -> 6 | BA10: 420 | BB10: 462 | BC10: 180 | BD10: 198 | BE10: 300 | BF10: 330 | BG10: 432.75 | BH10: =MAX(BB10, BD10, BF10) - MIN(BB10, BD10, BF10) -> 264 | BI10: =BH10/MIN(BB10, BD10, BF10) -> 1.3333333 | BJ10: =(BD10-BG10)/BG10 -> -0.54246101 | BK10: =(BC10-BE10)/BE10 -> -0.4 | BM10: =BM9 + 1 -> 6 | BN10: 420 | BO10: 462 | BP10: 270 | BQ10: 297 | BR10: 360 | BS10: 396 | BT10: 522.75 | BU10: =MAX(BO10, BQ10, BS10) - MIN(BO10, BQ10, BS10) -> 165 | BV10: =BU10/MIN(BO10, BQ10, BS10) -> 0.55555556 | BW10: =(BP10-BR10)/BR10 -> -0.25
A11: 7 | B11: =B10 + 1 -> 7 | C11: 105 | D11: 115.5 | E11: 126 | F11: 138.6 | G11: 105 | H11: 115.5 | I11: 363 | J11: =MAX(D11, F11, H11) - MIN(D11, F11, H11) -> 23.1 | K11: =J11/MIN(D11, F11, H11) -> 0.2 | L11: =(F11-I11)/F11 -> -1.6190476 | M11: =(F11-H11)/F11 -> 0.16666667 | O11: =O10 + 1 -> 7 | P11: 245 | Q11: 269.5 | R11: 140 | S11: 154 | T11: 175 | U11: 192.5 | V11: 398 | W11: =MAX(Q11, S11, U11) - MIN(Q11, S11, U11) -> 115.5 | X11: =(R11-T11)/R11 -> -0.25 | Y11: =(S11-V11)/S11 -> -1.5844156 | AA11: =AA10 + 1 -> 7 | AB11: 280 | AC11: 308 | AD11: 175 | AE11: 192.5 | AF11: 350 | AG11: 385 | AH11: 398 | AI11: =MAX(AC11, AE11, AG11) - MIN(AC11, AE11, AG11) -> 192.5 | AJ11: =(AE11-AG11)/AG11 -> -0.5 | AK11: =(AE11-AH11)/AH11 -> -0.51633166 | AM11: =AM10 + 1 -> 7 | AN11: 490 | AO11: 539 | AP11: 196 | AQ11: 215.6 | AR11: 385 | AS11: 423.5 | AT11: 476.25 | AU11: =MAX(AO11, AQ11, AS11) - MIN(AO11, AQ11, AS11) -> 323.4 | AV11: =AU11/MIN(AO11, AQ11, AS11) -> 1.5 | AW11: =(AP11-AR11)/AR11 -> -0.49090909 | AX11: =(AQ11-AT11)/AT11 -> -0.54729659 | AZ11: =AZ10 + 1 -> 7 | BA11: 490 | BB11: 539 | BC11: 210 | BD11: 231 | BE11: 350 | BF11: 385 | BG11: 504.25 | BH11: =MAX(BB11, BD11, BF11) - MIN(BB11, BD11, BF11) -> 308 | BI11: =BH11/MIN(BB11, BD11, BF11) -> 1.3333333 | BJ11: =(BD11-BG11)/BG11 -> -0.5418939 | BK11: =(BC11-BE11)/BE11 -> -0.4 | BM11: =BM10 + 1 -> 7 | BN11: 490 | BO11: 539 | BP11: 315 | BQ11: 346.5 | BR11: 420 | BS11: 462 | BT11: 609.25 | BU11: =MAX(BO11, BQ11, BS11) - MIN(BO11, BQ11, BS11) -> 192.5 | BV11: =BU11/MIN(BO11, BQ11, BS11) -> 0.55555556 | BW11: =(BP11-BR11)/BR11 -> -0.25
A12: 8 | B12: =B11 + 1 -> 8 | C12: 120 | D12: 132 | E12: 144 | F12: 158.4 | G12: 120 | H12: 132 | I12: 414.5 | J12: =MAX(D12, F12, H12) - MIN(D12, F12, H12) -> 26.4 | K12: =J12/MIN(D12, F12, H12) -> 0.2 | L12: =(F12-I12)/F12 -> -1.6167929 | M12: =(F12-H12)/F12 -> 0.16666667 | O12: =O11 + 1 -> 8 | P12: 280 | Q12: 308 | R12: 160 | S12: 176 | T12: 200 | U12: 220 | V12: 454.5 | W12: =MAX(Q12, S12, U12) - MIN(Q12, S12, U12) -> 132 | X12: =(R12-T12)/R12 -> -0.25 | Y12: =(S12-V12)/S12 -> -1.5823864 | AA12: =AA11 + 1 -> 8 | AB12: 320 | AC12: 352 | AD12: 200 | AE12: 220 | AF12: 400 | AG12: 440 | AH12: 454.5 | AI12: =MAX(AC12, AE12, AG12) - MIN(AC12, AE12, AG12) -> 220 | AJ12: =(AE12-AG12)/AG12 -> -0.5 | AK12: =(AE12-AH12)/AH12 -> -0.5159516 | AM12: =AM11 + 1 -> 8 | AN12: 560 | AO12: 616 | AP12: 224 | AQ12: 246.4 | AR12: 440 | AS12: 484 | AT12: 543.75 | AU12: =MAX(AO12, AQ12, AS12) - MIN(AO12, AQ12, AS12) -> 369.6 | AV12: =AU12/MIN(AO12, AQ12, AS12) -> 1.5 | AW12: =(AP12-AR12)/AR12 -> -0.49090909 | AX12: =(AQ12-AT12)/AT12 -> -0.54685057 | AZ12: =AZ11 + 1 -> 8 | BA12: 560 | BB12: 616 | BC12: 240 | BD12: 264 | BE12: 400 | BF12: 440 | BG12: 575.75 | BH12: =MAX(BB12, BD12, BF12) - MIN(BB12, BD12, BF12) -> 352 | BI12: =BH12/MIN(BB12, BD12, BF12) -> 1.3333333 | BJ12: =(BD12-BG12)/BG12 -> -0.54146765 | BK12: =(BC12-BE12)/BE12 -> -0.4 | BM12: =BM11 + 1 -> 8 | BN12: 560 | BO12: 616 | BP12: 360 | BQ12: 396 | BR12: 480 | BS12: 528 | BT12: 695.75 | BU12: =MAX(BO12, BQ12, BS12) - MIN(BO12, BQ12, BS12) -> 220 | BV12: =BU12/MIN(BO12, BQ12, BS12) -> 0.55555556 | BW12: =(BP12-BR12)/BR12 -> -0.25
A13: 9 | B13: =B12 + 1 -> 9 | C13: 135 | D13: 148.5 | E13: 162 | F13: 178.2 | G13: 135 | H13: 148.5 | I13: 466 | J13: =MAX(D13, F13, H13) - MIN(D13, F13, H13) -> 29.7 | K13: =J13/MIN(D13, F13, H13) -> 0.2 | L13: =(F13-I13)/F13 -> -1.6150393 | M13: =(F13-H13)/F13 -> 0.16666667 | O13: =O12 + 1 -> 9 | P13: 315 | Q13: 346.5 | R13: 180 | S13: 198 | T13: 225 | U13: 247.5 | V13: 511 | W13: =MAX(Q13, S13, U13) - MIN(Q13, S13, U13) -> 148.5 | X13: =(R13-T13)/R13 -> -0.25 | Y13: =(S13-V13)/S13 -> -1.5808081 | AA13: =AA12 + 1 -> 9 | AB13: 360 | AC13: 396 | AD13: 225 | AE13: 247.5 | AF13: 450 | AG13: 495 | AH13: 511 | AI13: =MAX(AC13, AE13, AG13) - MIN(AC13, AE13, AG13) -> 247.5 | AJ13: =(AE13-AG13)/AG13 -> -0.5 | AK13: =(AE13-AH13)/AH13 -> -0.51565558 | AM13: =AM12 + 1 -> 9 | AN13: 630 | AO13: 693 | AP13: 252 | AQ13: 277.2 | AR13: 495 | AS13: 544.5 | AT13: 611.25 | AU13: =MAX(AO13, AQ13, AS13) - MIN(AO13, AQ13, AS13) -> 415.8 | AV13: =AU13/MIN(AO13, AQ13, AS13) -> 1.5 | AW13: =(AP13-AR13)/AR13 -> -0.49090909 | AX13: =(AQ13-AT13)/AT13 -> -0.54650307 | AZ13: =AZ12 + 1 -> 9 | BA13: 630 | BB13: 693 | BC13: 270 | BD13: 297 | BE13: 450 | BF13: 495 | BG13: 647.25 | BH13: =MAX(BB13, BD13, BF13) - MIN(BB13, BD13, BF13) -> 396 | BI13: =BH13/MIN(BB13, BD13, BF13) -> 1.3333333 | BJ13: =(BD13-BG13)/BG13 -> -0.54113557 | BK13: =(BC13-BE13)/BE13 -> -0.4 | BM13: =BM12 + 1 -> 9 | BN13: 630 | BO13: 693 | BP13: 405 | BQ13: 445.5 | BR13: 540 | BS13: 594 | BT13: 782.25 | BU13: =MAX(BO13, BQ13, BS13) - MIN(BO13, BQ13, BS13) -> 247.5 | BV13: =BU13/MIN(BO13, BQ13, BS13) -> 0.55555556 | BW13: =(BP13-BR13)/BR13 -> -0.25
A14: 10 | B14: =B13 + 1 -> 10 | C14: 150 | D14: 165 | E14: 180 | F14: 198 | G14: 150 | H14: 165 | I14: 517.5 | J14: =MAX(D14, F14, H14) - MIN(D14, F14, H14) -> 33 | K14: =J14/MIN(D14, F14, H14) -> 0.2 | L14: =(F14-I14)/F14 -> -1.6136364 | M14: =(F14-H14)/F14 -> 0.16666667 | O14: =O13 + 1 -> 10 | P14: 350 | Q14: 385 | R14: 200 | S14: 220 | T14: 250 | U14: 275 | V14: 567.5 | W14: =MAX(Q14, S14, U14) - MIN(Q14, S14, U14) -> 165 | X14: =(R14-T14)/R14 -> -0.25 | Y14: =(S14-V14)/S14 -> -1.5795455 | AA14: =AA13 + 1 -> 10 | AB14: 400 | AC14: 440 | AD14: 250 | AE14: 275 | AF14: 500 | AG14: 550 | AH14: 567.5 | AI14: =MAX(AC14, AE14, AG14) - MIN(AC14, AE14, AG14) -> 275 | AJ14: =(AE14-AG14)/AG14 -> -0.5 | AK14: =(AE14-AH14)/AH14 -> -0.5154185 | AM14: =AM13 + 1 -> 10 | AN14: 700 | AO14: 770 | AP14: 280 | AQ14: 308 | AR14: 550 | AS14: 605 | AT14: 678.75 | AU14: =MAX(AO14, AQ14, AS14) - MIN(AO14, AQ14, AS14) -> 462 | AV14: =AU14/MIN(AO14, AQ14, AS14) -> 1.5 | AW14: =(AP14-AR14)/AR14 -> -0.49090909 | AX14: =(AQ14-AT14)/AT14 -> -0.54622468 | AZ14: =AZ13 + 1 -> 10 | BA14: 700 | BB14: 770 | BC14: 300 | BD14: 330 | BE14: 500 | BF14: 550 | BG14: 718.75 | BH14: =MAX(BB14, BD14, BF14) - MIN(BB14, BD14, BF14) -> 440 | BI14: =BH14/MIN(BB14, BD14, BF14) -> 1.3333333 | BJ14: =(BD14-BG14)/BG14 -> -0.54086957 | BK14: =(BC14-BE14)/BE14 -> -0.4 | BM14: =BM13 + 1 -> 10 | BN14: 700 | BO14: 770 | BP14: 450 | BQ14: 495 | BR14: 600 | BS14: 660 | BT14: 868.75 | BU14: =MAX(BO14, BQ14, BS14) - MIN(BO14, BQ14, BS14) -> 275 | BV14: =BU14/MIN(BO14, BQ14, BS14) -> 0.55555556 | BW14: =(BP14-BR14)/BR14 -> -0.25
A15: 11 | B15: =B14 + 1 -> 11 | C15: 165 | D15: 181.5 | E15: 198 | F15: 217.8 | G15: 165 | H15: 181.5 | I15: 569 | J15: =MAX(D15, F15, H15) - MIN(D15, F15, H15) -> 36.3 | K15: =J15/MIN(D15, F15, H15) -> 0.2 | L15: =(F15-I15)/F15 -> -1.6124885 | M15: =(F15-H15)/F15 -> 0.16666667 | O15: =O14 + 1 -> 11 | P15: 385 | Q15: 423.5 | R15: 220 | S15: 242 | T15: 275 | U15: 302.5 | V15: 624 | W15: =MAX(Q15, S15, U15) - MIN(Q15, S15, U15) -> 181.5 | X15: =(R15-T15)/R15 -> -0.25 | Y15: =(S15-V15)/S15 -> -1.5785124 | AA15: =AA14 + 1 -> 11 | AB15: 440 | AC15: 484 | AD15: 275 | AE15: 302.5 | AF15: 550 | AG15: 605 | AH15: 624 | AI15: =MAX(AC15, AE15, AG15) - MIN(AC15, AE15, AG15) -> 302.5 | AJ15: =(AE15-AG15)/AG15 -> -0.5 | AK15: =(AE15-AH15)/AH15 -> -0.51522436 | AM15: =AM14 + 1 -> 11 | AN15: 770 | AO15: 847 | AP15: 308 | AQ15: 338.8 | AR15: 605 | AS15: 665.5 | AT15: 746.25 | AU15: =MAX(AO15, AQ15, AS15) - MIN(AO15, AQ15, AS15) -> 508.2 | AV15: =AU15/MIN(AO15, AQ15, AS15) -> 1.5 | AW15: =(AP15-AR15)/AR15 -> -0.49090909 | AX15: =(AQ15-AT15)/AT15 -> -0.54599665 | AZ15: =AZ14 + 1 -> 11 | BA15: 770 | BB15: 847 | BC15: 330 | BD15: 363 | BE15: 550 | BF15: 605 | BG15: 790.25 | BH15: =MAX(BB15, BD15, BF15) - MIN(BB15, BD15, BF15) -> 484 | BI15: =BH15/MIN(BB15, BD15, BF15) -> 1.3333333 | BJ15: =(BD15-BG15)/BG15 -> -0.54065169 | BK15: =(BC15-BE15)/BE15 -> -0.4 | BM15: =BM14 + 1 -> 11 | BN15: 770 | BO15: 847 | BP15: 495 | BQ15: 544.5 | BR15: 660 | BS15: 726 | BT15: 955.25 | BU15: =MAX(BO15, BQ15, BS15) - MIN(BO15, BQ15, BS15) -> 302.5 | BV15: =BU15/MIN(BO15, BQ15, BS15) -> 0.55555556 | BW15: =(BP15-BR15)/BR15 -> -0.25
A16: 12 | B16: =B15 + 1 -> 12 | C16: 180 | D16: 198 | E16: 216 | F16: 237.6 | G16: 180 | H16: 198 | I16: 620.5 | J16: =MAX(D16, F16, H16) - MIN(D16, F16, H16) -> 39.6 | K16: =J16/MIN(D16, F16, H16) -> 0.2 | L16: =(F16-I16)/F16 -> -1.611532 | M16: =(F16-H16)/F16 -> 0.16666667 | O16: =O15 + 1 -> 12 | P16: 420 | Q16: 462 | R16: 240 | S16: 264 | T16: 300 | U16: 330 | V16: 680.5 | W16: =MAX(Q16, S16, U16) - MIN(Q16, S16, U16) -> 198 | X16: =(R16-T16)/R16 -> -0.25 | Y16: =(S16-V16)/S16 -> -1.5776515 | AA16: =AA15 + 1 -> 12 | AB16: 480 | AC16: 528 | AD16: 300 | AE16: 330 | AF16: 600 | AG16: 660 | AH16: 680.5 | AI16: =MAX(AC16, AE16, AG16) - MIN(AC16, AE16, AG16) -> 330 | AJ16: =(AE16-AG16)/AG16 -> -0.5 | AK16: =(AE16-AH16)/AH16 -> -0.51506245 | AM16: =AM15 + 1 -> 12 | AN16: 840 | AO16: 924 | AP16: 336 | AQ16: 369.6 | AR16: 660 | AS16: 726 | AT16: 813.75 | AU16: =MAX(AO16, AQ16, AS16) - MIN(AO16, AQ16, AS16) -> 554.4 | AV16: =AU16/MIN(AO16, AQ16, AS16) -> 1.5 | AW16: =(AP16-AR16)/AR16 -> -0.49090909 | AX16: =(AQ16-AT16)/AT16 -> -0.54580645 | AZ16: =AZ15 + 1 -> 12 | BA16: 840 | BB16: 924 | BC16: 360 | BD16: 396 | BE16: 600 | BF16: 660 | BG16: 861.75 | BH16: =MAX(BB16, BD16, BF16) - MIN(BB16, BD16, BF16) -> 528 | BI16: =BH16/MIN(BB16, BD16, BF16) -> 1.3333333 | BJ16: =(BD16-BG16)/BG16 -> -0.54046997 | BK16: =(BC16-BE16)/BE16 -> -0.4 | BM16: =BM15 + 1 -> 12 | BN16: 840 | BO16: 924 | BP16: 540 | BQ16: 594 | BR16: 720 | BS16: 792 | BT16: 1041.75 | BU16: =MAX(BO16, BQ16, BS16) - MIN(BO16, BQ16, BS16) -> 330 | BV16: =BU16/MIN(BO16, BQ16, BS16) -> 0.55555556 | BW16: =(BP16-BR16)/BR16 -> -0.25
A17: 13 | B17: =B16 + 1 -> 13 | C17: 195 | D17: 214.5 | E17: 234 | F17: 257.4 | G17: 195 | H17: 214.5 | I17: 672 | J17: =MAX(D17, F17, H17) - MIN(D17, F17, H17) -> 42.9 | K17: =J17/MIN(D17, F17, H17) -> 0.2 | L17: =(F17-I17)/F17 -> -1.6107226 | M17: =(F17-H17)/F17 -> 0.16666667 | O17: =O16 + 1 -> 13 | P17: 455 | Q17: 500.5 | R17: 260 | S17: 286 | T17: 325 | U17: 357.5 | V17: 737 | W17: =MAX(Q17, S17, U17) - MIN(Q17, S17, U17) -> 214.5 | X17: =(R17-T17)/R17 -> -0.25 | Y17: =(S17-V17)/S17 -> -1.5769231 | AA17: =AA16 + 1 -> 13 | AB17: 520 | AC17: 572 | AD17: 325 | AE17: 357.5 | AF17: 650 | AG17: 715 | AH17: 737 | AI17: =MAX(AC17, AE17, AG17) - MIN(AC17, AE17, AG17) -> 357.5 | AJ17: =(AE17-AG17)/AG17 -> -0.5 | AK17: =(AE17-AH17)/AH17 -> -0.51492537 | AM17: =AM16 + 1 -> 13 | AN17: 910 | AO17: 1001 | AP17: 364 | AQ17: 400.4 | AR17: 715 | AS17: 786.5 | AT17: 881.25 | AU17: =MAX(AO17, AQ17, AS17) - MIN(AO17, AQ17, AS17) -> 600.6 | AV17: =AU17/MIN(AO17, AQ17, AS17) -> 1.5 | AW17: =(AP17-AR17)/AR17 -> -0.49090909 | AX17: =(AQ17-AT17)/AT17 -> -0.54564539 | AZ17: =AZ16 + 1 -> 13 | BA17: 910 | BB17: 1001 | BC17: 390 | BD17: 429 | BE17: 650 | BF17: 715 | BG17: 933.25 | BH17: =MAX(BB17, BD17, BF17) - MIN(BB17, BD17, BF17) -> 572 | BI17: =BH17/MIN(BB17, BD17, BF17) -> 1.3333333 | BJ17: =(BD17-BG17)/BG17 -> -0.5403161 | BK17: =(BC17-BE17)/BE17 -> -0.4 | BM17: =BM16 + 1 -> 13 | BN17: 910 | BO17: 1001 | BP17: 585 | BQ17: 643.5 | BR17: 780 | BS17: 858 | BT17: 1128.25 | BU17: =MAX(BO17, BQ17, BS17) - MIN(BO17, BQ17, BS17) -> 357.5 | BV17: =BU17/MIN(BO17, BQ17, BS17) -> 0.55555556 | BW17: =(BP17-BR17)/BR17 -> -0.25
A18: 14 | B18: =B17 + 1 -> 14 | C18: 210 | D18: 231 | E18: 252 | F18: 277.2 | G18: 210 | H18: 231 | I18: 723.5 | J18: =MAX(D18, F18, H18) - MIN(D18, F18, H18) -> 46.2 | K18: =J18/MIN(D18, F18, H18) -> 0.2 | L18: =(F18-I18)/F18 -> -1.6100289 | M18: =(F18-H18)/F18 -> 0.16666667 | O18: =O17 + 1 -> 14 | P18: 490 | Q18: 539 | R18: 280 | S18: 308 | T18: 350 | U18: 385 | V18: 793.5 | W18: =MAX(Q18, S18, U18) - MIN(Q18, S18, U18) -> 231 | X18: =(R18-T18)/R18 -> -0.25 | Y18: =(S18-V18)/S18 -> -1.5762987 | AA18: =AA17 + 1 -> 14 | AB18: 560 | AC18: 616 | AD18: 350 | AE18: 385 | AF18: 700 | AG18: 770 | AH18: 793.5 | AI18: =MAX(AC18, AE18, AG18) - MIN(AC18, AE18, AG18) -> 385 | AJ18: =(AE18-AG18)/AG18 -> -0.5 | AK18: =(AE18-AH18)/AH18 -> -0.51480781 | AM18: =AM17 + 1 -> 14 | AN18: 980 | AO18: 1078 | AP18: 392 | AQ18: 431.2 | AR18: 770 | AS18: 847 | AT18: 948.75 | AU18: =MAX(AO18, AQ18, AS18) - MIN(AO18, AQ18, AS18) -> 646.8 | AV18: =AU18/MIN(AO18, AQ18, AS18) -> 1.5 | AW18: =(AP18-AR18)/AR18 -> -0.49090909 | AX18: =(AQ18-AT18)/AT18 -> -0.54550725 | AZ18: =AZ17 + 1 -> 14 | BA18: 980 | BB18: 1078 | BC18: 420 | BD18: 462 | BE18: 700 | BF18: 770 | BG18: 1004.75 | BH18: =MAX(BB18, BD18, BF18) - MIN(BB18, BD18, BF18) -> 616 | BI18: =BH18/MIN(BB18, BD18, BF18) -> 1.3333333 | BJ18: =(BD18-BG18)/BG18 -> -0.54018413 | BK18: =(BC18-BE18)/BE18 -> -0.4 | BM18: =BM17 + 1 -> 14 | BN18: 980 | BO18: 1078 | BP18: 630 | BQ18: 693 | BR18: 840 | BS18: 924 | BT18: 1214.75 | BU18: =MAX(BO18, BQ18, BS18) - MIN(BO18, BQ18, BS18) -> 385 | BV18: =BU18/MIN(BO18, BQ18, BS18) -> 0.55555556 | BW18: =(BP18-BR18)/BR18 -> -0.25
... A54: 50 | B54: =B53 + 1 -> 50 | C54: 750 | D54: 825 | E54: 900 | F54: 990 | G54: 750 | H54: 825 | I54: 2577.5 | J54: =MAX(D54, F54, H54) - MIN(D54, F54, H54) -> 165 | K54: =J54/MIN(D54, F54, H54) -> 0.2 | L54: =(F54-I54)/F54 -> -1.6035354 | M54: =(F54-H54)/F54 -> 0.16666667 | O54: =O53 + 1 -> 50 | P54: 1750 | Q54: 1925 | R54: 1000 | S54: 1100 | T54: 1250 | U54: 1375 | V54: 2827.5 | W54: =MAX(Q54, S54, U54) - MIN(Q54, S54, U54) -> 825 | X54: =(R54-T54)/R54 -> -0.25 | Y54: =(S54-V54)/S54 -> -1.5704545 | AA54: =AA53 + 1 -> 50 | AB54: 2000 | AC54: 2200 | AD54: 1250 | AE54: 1375 | AF54: 2500 | AG54: 2750 | AH54: 2827.5 | AI54: =MAX(AC54, AE54, AG54) - MIN(AC54, AE54, AG54) -> 1375 | AJ54: =(AE54-AG54)/AG54 -> -0.5 | AK54: =(AE54-AH54)/AH54 -> -0.51370469 | AM54: =AM53 + 1 -> 50 | AN54: 3500 | AO54: 3850 | AP54: 1400 | AQ54: 1540 | AR54: 2750 | AS54: 3025 | AT54: 3378.75 | AU54: =MAX(AO54, AQ54, AS54) - MIN(AO54, AQ54, AS54) -> 2310 | AV54: =AU54/MIN(AO54, AQ54, AS54) -> 1.5 | AW54: =(AP54-AR54)/AR54 -> -0.49090909 | AX54: =(AQ54-AT54)/AT54 -> -0.54421014 | AZ54: =AZ53 + 1 -> 50 | BA54: 3500 | BB54: 3850 | BC54: 1500 | BD54: 1650 | BE54: 2500 | BF54: 2750 | BG54: 3578.75 | BH54: =MAX(BB54, BD54, BF54) - MIN(BB54, BD54, BF54) -> 2200 | BI54: =BH54/MIN(BB54, BD54, BF54) -> 1.3333333 | BJ54: =(BD54-BG54)/BG54 -> -0.53894516 | BK54: =(BC54-BE54)/BE54 -> -0.4 | BM54: =BM53 + 1 -> 50 | BN54: 3500 | BO54: 3850 | BP54: 2250 | BQ54: 2475 | BR54: 3000 | BS54: 3300 | BT54: 4328.75 | BU54: =MAX(BO54, BQ54, BS54) - MIN(BO54, BQ54, BS54) -> 1375 | BV54: =BU54/MIN(BO54, BQ54, BS54) -> 0.55555556 | BW54: =(BP54-BR54)/BR54 -> -0.25
A55: AVERAGE DIFFERENCE % | K55: =AVERAGE(K5:K54) -> 0.26 | L55: =AVERAGE(L5:L54) -> -1.6088994 | M55: =AVERAGE(M7:M54) -> 0.16666667 | O55: AVERAGE DIFFERENCE % | X55: =AVERAGE(X5:X54) -> -0.25 | Y55: =AVERAGE(Y5:Y54) -> -1.5752822 | AA55: AVERAGE DIFFERENCE % | AJ55: =AVERAGE(AJ7:AJ54) -> -0.5 | AK55: =AVERAGE(AK7:AK54) -> -0.51461263 | AM55: AVERAGE DIFFERENCE % | AV55: =AVERAGE(AV5:AV54) -> 1.4638788 | AW55: =AVERAGE(AW7:AW54) -> -0.49090909 | AX55: =AVERAGE(AX7:AX54) -> -0.54527676 | AZ55: AVERAGE DIFFERENCE % | BI55: =AVERAGE(BI5:BI54) -> 1.3071111 | BJ55: =AVERAGE(BJ5:BJ54) -> -0.53996423 | BK55: =AVERAGE(BK5:BK54) -> -0.4 | BM55: AVERAGE DIFFERENCE % | BV55: =AVERAGE(BV5:BV54) -> 0.56166667 | BW55: =AVERAGE(BW5:BW54) -> -0.25
A57: WITHIN CITY | O57: WITHIN STATE | AA57: WITHIN ZONE | AM57: METRO TO METRO | AZ57: REST OF INDIA | BM57: SPECIAL DESTINATION
A58: DOCUMENT CHARGE BY SURFACE | O58: DOCUMENT CHARGE BY SURFACE | AA58: DOCUMENT CHARGE BY SURFACE | AM58: DOCUMENT CHARGE BY SURFACE | AZ58: DOCUMENT CHARGE BY SURFACE | BM58: DOCUMENT CHARGE BY SURFACE
A59: SR.NO. | B59: KGS | C59: PROFESSIONAL COURIER SERVICE | D59: TOTAL COST | E59: DTDC | F59: TOTAL COST | G59: SHREE MARUTI COURIER SERVICE | H59: TOTAL COST | I59: DIFF. | J59: %DIFF. | O59: KGS | P59: PROFESSIONAL COURIER SERVICE | Q59: TOTAL COST | R59: DTDC | S59: TOTAL COST | T59: SHREE MARUTI COURIER SERVICE | U59: TOTAL COST | V59: DIFF. | W59: %DIFF. | AA59: KGS | AB59: PROFESSIONAL COURIER SERVICE | AC59: TOTAL COST | AD59: DTDC | AE59: TOTAL COST | AF59: SHREE MARUTI COURIER SERVICE | AG59: TOTAL COST | AH59: DIFF. | AI59: %DIFF. | AM59: KGS | AN59: PROFESSIONAL COURIER SERVICE | AO59: TOTAL COST | AP59: DTDC | AQ59: TOTAL COST | AR59: SHREE MARUTI COURIER SERVICE | AS59: TOTAL COST | AT59: DIFF. | AU59: %DIFF. | AZ59: KGS | BA59: PROFESSIONAL COURIER SERVICE | BB59: TOTAL COST | BC59: DTDC | BD59: TOTAL COST | BE59: SHREE MARUTI COURIER SERVICE | BF59: TOTAL COST | BG59: DIFF. | BH59: %DIFF. | BM59: KGS | BN59: PROFESSIONAL COURIER SERVICE | BO59: TOTAL COST | BP59: DTDC | BQ59: TOTAL COST | BR59: SHREE MARUTI COURIER SERVICE | BS59: TOTAL COST | BT59: DIFF. | BU59: %DIFF.
B60: 0.1 | C60: 8 | D60: =C60 + 10%*C60 -> 8.8 | E60: 15 | F60: =E60+10%*E60 -> 16.5 | G60: 10 | H60: =G60 +10%*G60 -> 11 | I60: =MAX(C60, E60, G60) - MIN(C60, E60, G60) -> 7 | J60: =I60/MIN(C60, E60, G60) -> 0.875 | O60: 0.1 | P60: 15 | Q60: =P60 + 10%*P60 -> 16.5 | R60: 16 | S60: =R60+10%*R60 -> 17.6 | T60: 13 | U60: =T60 +10%*T60 -> 14.3 | V60: =MAX(P60, R60, T60) - MIN(P60, R60, T60) -> 3 | W60: =V60/MIN(P60, R60, T60) -> 0.23076923 | AA60: 0.1 | AB60: 20 | AC60: =AB60 + 10%*AB60 -> 22 | AD60: 20.5 | AE60: =AD60+10%*AD60 -> 22.55 | AF60: 20 | AG60: =AF60 +10%*AF60 -> 22 | AH60: =MAX(AB60, AD60, AF60) - MIN(AB60, AD60, AF60) -> 0.5 | AI60: =AH60/MIN(AB60, AD60, AF60) -> 0.025 | AM60: 0.1 | AN60: 35 | AO60: =AN60 + 10%*AN60 -> 38.5 | AP60: 33.5 | AQ60: =AP60+10%*AP60 -> 36.85 | AR60: 20 | AS60: =AR60 +10%*AR60 -> 22 | AT60: =MAX(AN60, AP60, AR60) - MIN(AN60, AP60, AR60) -> 15 | AU60: =AT60/MIN(AN60, AP60, AR60) -> 0.75 | AZ60: 0.1 | BA60: 35 | BB60: =BA60 + 10%*BA60 -> 38.5 | BC60: 36.5 | BD60: =BC60+10%*BC60 -> 40.15 | BE60: 25 | BF60: =BE60 +10%*BE60 -> 27.5 | BG60: =MAX(BA60, BC60, BE60) - MIN(BA60, BC60, BE60) -> 11.5 | BH60: =BG60/MIN(BA60, BC60, BE60) -> 0.46 | BM60: 0.1 | BN60: 35 | BO60: =BN60 + 10%*BN60 -> 38.5 | BP60: 43 | BQ60: =BP60+BP60*10% -> 47.3 | BR60: 60 | BS60: =BR60 +10%*BR60 -> 66 | BT60: =MAX(BN60, BP60, BR60) - MIN(BN60, BP60, BR60) -> 25 | BU60: =BT60/MIN(BN60, BP60, BR60) -> 0.71428571
B61: 0.25 | C61: 10 | D61: =C61 + 10%*C61 -> 11 | E61: 15.5 | F61: =E61+10%*E61 -> 17.05 | G61: 12 | H61: =G61 +10%*G61 -> 13.2 | I61: =MAX(C61, E61, G61) - MIN(C61, E61, G61) -> 5.5 | J61: =I61/MIN(C61, E61, G61) -> 0.55 | O61: 0.25 | P61: 20 | Q61: =P61 + 10%*P61 -> 22 | R61: 16.5 | S61: =R61+10%*R61 -> 18.15 | T61: 20 | U61: =T61 +10%*T61 -> 22 | V61: =MAX(P61, R61, T61) - MIN(P61, R61, T61) -> 3.5 | W61: =V61/MIN(P61, R61, T61) -> 0.21212121 | AA61: 0.25 | AB61: 25 | AC61: =AB61 + 10%*AB61 -> 27.5 | AD61: 22 | AE61: =AD61+10%*AD61 -> 24.2 | AF61: 25 | AG61: =AF61 +10%*AF61 -> 27.5 | AH61: =MAX(AB61, AD61, AF61) - MIN(AB61, AD61, AF61) -> 3 | AI61: =AH61/MIN(AB61, AD61, AF61) -> 0.13636364 | AM61: 0.25 | AN61: 40 | AO61: =AN61 + 10%*AN61 -> 44 | AP61: 35.5 | AQ61: =AP61+10%*AP61 -> 39.05 | AR61: 25 | AS61: =AR61 +10%*AR61 -> 27.5 | AT61: =MAX(AN61, AP61, AR61) - MIN(AN61, AP61, AR61) -> 15 | AU61: =AT61/MIN(AN61, AP61, AR61) -> 0.6 | AZ61: 0.25 | BA61: 40 | BB61: =BA61 + 10%*BA61 -> 44 | BC61: 39.5 | BD61: =BC61+10%*BC61 -> 43.45 | BE61: 30 | BF61: =BE61 +10%*BE61 -> 33 | BG61: =MAX(BA61, BC61, BE61) - MIN(BA61, BC61, BE61) -> 10 | BH61: =BG61/MIN(BA61, BC61, BE61) -> 0.33333333 | BM61: 0.25 | BN61: 40 | BO61: =BN61 + 10%*BN61 -> 44 | BP61: 45.5 | BQ61: =BP61+BP61*10% -> 50.05 | BR61: 60 | BS61: =BR61 +10%*BR61 -> 66 | BT61: =MAX(BN61, BP61, BR61) - MIN(BN61, BP61, BR61) -> 20 | BU61: =BT61/MIN(BN61, BP61, BR61) -> 0.5
B62: 0.5 | C62: 13 | D62: =C62 + 10%*C62 -> 14.3 | E62: 16 | F62: =E62+10%*E62 -> 17.6 | G62: 15 | H62: =G62 +10%*G62 -> 16.5 | I62: =MAX(C62, E62, G62) - MIN(C62, E62, G62) -> 3 | J62: =I62/MIN(C62, E62, G62) -> 0.23076923 | O62: 0.5 | P62: 25 | Q62: =P62 + 10%*P62 -> 27.5 | R62: 17 | S62: =R62+10%*R62 -> 18.7 | T62: 25 | U62: =T62 +10%*T62 -> 27.5 | V62: =MAX(P62, R62, T62) - MIN(P62, R62, T62) -> 8 | W62: =V62/MIN(P62, R62, T62) -> 0.47058824 | AA62: 0.5 | AB62: 30 | AC62: =AB62 + 10%*AB62 -> 33 | AD62: 23 | AE62: =AD62+10%*AD62 -> 25.3 | AF62: 30 | AG62: =AF62 +10%*AF62 -> 33 | AH62: =MAX(AB62, AD62, AF62) - MIN(AB62, AD62, AF62) -> 7 | AI62: =AH62/MIN(AB62, AD62, AF62) -> 0.30434783 | AM62: 0.5 | AN62: 50 | AO62: =AN62 + 10%*AN62 -> 55 | AP62: 45 | AQ62: =AP62+10%*AP62 -> 49.5 | AR62: 30 | AS62: =AR62 +10%*AR62 -> 33 | AT62: =MAX(AN62, AP62, AR62) - MIN(AN62, AP62, AR62) -> 20 | AU62: =AT62/MIN(AN62, AP62, AR62) -> 0.66666667 | AZ62: 0.5 | BA62: 50 | BB62: =BA62 + 10%*BA62 -> 55 | BC62: 50 | BD62: =BC62+10%*BC62 -> 55 | BE62: 35 | BF62: =BE62 +10%*BE62 -> 38.5 | BG62: =MAX(BA62, BC62, BE62) - MIN(BA62, BC62, BE62) -> 15 | BH62: =BG62/MIN(BA62, BC62, BE62) -> 0.42857143 | BM62: 0.5 | BN62: 50 | BO62: =BN62 + 10%*BN62 -> 55 | BP62: 65 | BQ62: =BP62+BP62*10% -> 71.5 | BR62: 60 | BS62: =BR62 +10%*BR62 -> 66 | BT62: =MAX(BN62, BP62, BR62) - MIN(BN62, BP62, BR62) -> 15 | BU62: =BT62/MIN(BN62, BP62, BR62) -> 0.3
B63: 1 | C63: 15 | D63: =C63 + 10%*C63 -> 16.5 | E63: =E62 + 9.5 -> 25.5 | F63: =E63+10%*E63 -> 28.05 | G63: 25 | H63: =G63 +10%*G63 -> 27.5 | I63: =MAX(C63, E63, G63) - MIN(C63, E63, G63) -> 10.5 | J63: =I63/MIN(C63, E63, G63) -> 0.7 | O63: 1 | P63: 30 | Q63: =P63 + 10%*P63 -> 33 | R63: =R62 + 10.5 -> 27.5 | S63: =R63+10%*R63 -> 30.25 | T63: 35 | U63: =T63 +10%*T63 -> 38.5 | V63: =MAX(P63, R63, T63) - MIN(P63, R63, T63) -> 7.5 | W63: =V63/MIN(P63, R63, T63) -> 0.27272727 | AA63: 1 | AB63: 35 | AC63: =AB63 + 10%*AB63 -> 38.5 | AD63: =AD62 +17 -> 40 | AE63: =AD63+10%*AD63 -> 44 | AF63: 45 | AG63: =AF63 +10%*AF63 -> 49.5 | AH63: =MAX(AB63, AD63, AF63) - MIN(AB63, AD63, AF63) -> 10 | AI63: =AH63/MIN(AB63, AD63, AF63) -> 0.28571429 | AM63: 1 | AN63: 65 | AO63: =AN63 + 10%*AN63 -> 71.5 | AP63: =AP62+30 -> 75 | AQ63: =AP63+10%*AP63 -> 82.5 | AR63: 45 | AS63: =AR63 +10%*AR63 -> 49.5 | AT63: =MAX(AN63, AP63, AR63) - MIN(AN63, AP63, AR63) -> 30 | AU63: =AT63/MIN(AN63, AP63, AR63) -> 0.66666667 | AZ63: 1 | BA63: 65 | BB63: =BA63 + 10%*BA63 -> 71.5 | BC63: =BC62+35 -> 85 | BD63: =BC63+10%*BC63 -> 93.5 | BE63: 50 | BF63: =BE63 +10%*BE63 -> 55 | BG63: =MAX(BA63, BC63, BE63) - MIN(BA63, BC63, BE63) -> 35 | BH63: =BG63/MIN(BA63, BC63, BE63) -> 0.7 | BM63: 1 | BN63: 65 | BO63: =BN63 + 10%*BN63 -> 71.5 | BP63: =BP62+60 -> 125 | BQ63: =BP63+BP63*10% -> 137.5 | BR63: 60 | BS63: =BR63 +10%*BR63 -> 66 | BT63: =MAX(BN63, BP63, BR63) - MIN(BN63, BP63, BR63) -> 65 | BU63: =BT63/MIN(BN63, BP63, BR63) -> 1.0833333
A64: AVERAGE DIFFERENCE % | J64: =AVERAGE(J60:J63) -> 0.58894231 | O64: AVERAGE DIFFERENCE % | W64: =AVERAGE(W60:W63) -> 0.29655149 | AA64: AVERAGE DIFFERENCE % | AI64: =AVERAGE(AI60:AI63) -> 0.18785644 | AM64: AVERAGE DIFFERENCE % | AU64: =AVERAGE(AU60:AU63) -> 0.67083333 | AZ64: AVERAGE DIFFERENCE % | BH64: =AVERAGE(BH60:BH63) -> 0.48047619 | BM64: AVERAGE DIFFERENCE % | BU64: =AVERAGE(BU60:BU63) -> 0.64940476

Sheet DTDC PREV VS CURRENT
A1: DOMESTIC COURIER CHARGE
A2: WITHIN CITY | J2: WITHIN STATE | S2: WITHIN ZONE | AB2: METRO TO METRO | AK2: REST OF INDIA | AT2: SPECIAL DESTINATION
A3: NON-DOCUMENT CHARGE BY SURFACE | J3: NON-DOCUMENT CHARGE BY SURFACE | S3: NON-DOCUMENT CHARGE BY SURFACE | AB3: NON-DOCUMENT CHARGE BY SURFACE | AK3: NON-DOCUMENT CHARGE BY SURFACE | AT3: NON-DOCUMENT CHARGE BY SURFACE
A4: SR.NO. | B4: KGS | C4: DTDC PREV | D4: TOTAL COST | E4: DTDC CURRENT | F4: TOTAL COST | G4: DIFF. | H4: %DIFF. | J4: SR.NO. | K4: KGS | L4: DTDC PREV | M4: TOTAL COST | N4: DTDC CURRENT | O4: TOTAL COST | P4: DIFF. | Q4: %DIFF. | S4: SR.NO. | T4: KGS | U4: DTDC PREV | V4: TOTAL COST | W4: DTDC CURRENT | X4: TOTAL COST | Y4: DIFF. | Z4: %DIFF. | AB4: SR.NO. | AC4: KGS | AD4: DTDC PREV | AE4: TOTAL COST | AF4: DTDC CURRENT | AG4: TOTAL COST | AH4: DIFF. | AI4: %DIFF. | AK4: SR.NO. | AL4: KGS | AM4: DTDC PREV | AN4: TOTAL COST | AO4: DTDC CURRENT | AP4: TOTAL COST | AQ4: DIFF. | AR4: %DIFF. | AT4: SR.NO. | AU4: KGS | AV4: DTDC PREV | AW4: TOTAL COST | AX4: DTDC CURRENT | AY4: TOTAL COST | AZ4: DIFF. | BA4: %DIFF.
A5: {=_xlfn.SEQUENCE(50)} -> 1 | B5: 1 | C5: =18*3 -> 54 | D5: =C5 +C5*10% -> 59.4 | E5: {=VLOOKUP(B5:B54, WITHINCITY!B4:E53,4,0)} -> 54 | F5: {=VLOOKUP(B5:B54, WITHINCITY!B4:P53,15,0)} -> 59.4 | J5: {=_xlfn.SEQUENCE(50)} -> 1 | K5: 1 | L5: =20*3 -> 60 | M5: =L5 +L5*10% -> 66 | N5: {=VLOOKUP(K5:K54, WITHINSTATE!B4:E53,4,0)} -> 60 | O5: {=VLOOKUP(K5:K54, WITHINSTATE!B4:P53,15,0)} -> 66 | S5: {=_xlfn.SEQUENCE(50)} -> 1 | T5: 1 | U5: =25*3 -> 75 | V5: =U5 +U5*10% -> 82.5 | W5: {=VLOOKUP(T5:T54, WITHINZONE!B4:E53,4,0)} -> 75 | X5: {=VLOOKUP(T5:T54, WITHINZONE!B4:P53,15,0)} -> 82.5 | AB5: {=_xlfn.SEQUENCE(50)} -> 1 | AC5: 1 | AD5: =30*3 -> 90 | AE5: =AD5 +AD5*10% -> 99 | AF5: {=VLOOKUP(AC5:AC54, 'METRO TO METRO'!B4:E53,4,0)} -> 84 | AG5: {=VLOOKUP(AC5:AC54, 'METRO TO METRO'!B4:P53,15,0)} -> 92.4 | AK5: {=_xlfn.SEQUENCE(50)} -> 1 | AL5: 1 | AM5: =40*3 -> 120 | AN5: =AM5 +AM5*10% -> 132 | AO5: {=VLOOKUP(AL5:AL54, RESTOFINDIA!B4:E53,4,0)} -> 90 | AP5: {=VLOOKUP(AL5:AL54, RESTOFINDIA!B4:P53,15,0)} -> 99 | AT5: {=_xlfn.SEQUENCE(50)} -> 1 | AU5: 1 | AV5: =54*3 -> 162 | AW5: =AV5 +AV5*10% -> 178.2 | AX5: {=VLOOKUP(AU5:AU54, SPECIALDESTINATION!B4:E53,4,0)} -> 135 | AY5: {=VLOOKUP(AU5:AU54, SPECIALDESTINATION!B4:O53,14,0)} -> 148.5
A6: 2 | B6: =B5 + 1 -> 2 | C6: =18*3 -> 54 | D6: =C6 +C6*10% -> 59.4 | E6: 54 | F6: 59.4 | J6: 2 | K6: =K5 + 1 -> 2 | L6: =20*3 -> 60 | M6: =L6 +L6*10% -> 66 | N6: 60 | O6: 66 | S6: 2 | T6: =T5 + 1 -> 2 | U6: =25*3 -> 75 | V6: =U6 +U6*10% -> 82.5 | W6: 75 | X6: 82.5 | AB6: 2 | AC6: =AC5 + 1 -> 2 | AD6: =30*3 -> 90 | AE6: =AD6 +AD6*10% -> 99 | AF6: 84 | AG6: 92.4 | AK6: 2 | AL6: =AL5 + 1 -> 2 | AM6: =40*3 -> 120 | AN6: =AM6 +AM6*10% -> 132 | AO6: 90 | AP6: 99 | AT6: 2 | AU6: =AU5 + 1 -> 2 | AV6: =54*3 -> 162 | AW6: =AV6 +AV6*10% -> 178.2 | AX6: 135 | AY6: 148.5
A7: 3 | B7: =B6 + 1 -> 3 | C7: =18*3 -> 54 | D7: =C7 +C7*10% -> 59.4 | E7: 54 | F7: 59.4 | G7: =D7-F7 -> 0 | H7: =G7/F7 -> 0 | J7: 3 | K7: =K6 + 1 -> 3 | L7: =20*3 -> 60 | M7: =L7 +L7*10% -> 66 | N7: 60 | O7: 66 | P7: =M7-O7 -> 0 | Q7: =P7/O7 -> 0 | S7: 3 | T7: =T6 + 1 -> 3 | U7: =25*3 -> 75 | V7: =U7 +U7*10% -> 82.5 | W7: 75 | X7: 82.5 | Y7: =V7-X7 -> 0 | Z7: =Y7/X7 -> 0 | AB7: 3 | AC7: =AC6 + 1 -> 3 | AD7: =30*3 -> 90 | AE7: =AD7 +AD7*10% -> 99 | AF7: 84 | AG7: 92.4 | AH7: =AE7-AG7 -> 6.6 | AI7: =AH7/AG7 -> 0.071428571 | AK7: 3 | AL7: =AL6 + 1 -> 3 | AM7: =40*3 -> 120 | AN7: =AM7 +AM7*10% -> 132 | AO7: 90 | AP7: 99 | AQ7: =AN7-AP7 -> 33 | AR7: =AQ7/AP7 -> 0.33333333 | AT7: 3 | AU7: =AU6 + 1 -> 3 | AV7: =54*3 -> 162 | AW7: =AV7 +AV7*10% -> 178.2 | AX7: 135 | AY7: 148.5 | AZ7: =AW7-AY7 -> 29.7 | BA7: =AZ7/AY7 -> 0.2
A8: 4 | B8: =B7 + 1 -> 4 | C8: =18*B8 -> 72 | D8: =C8 +C8*10% -> 79.2 | E8: 72 | F8: 79.2 | G8: =D8-F8 -> 0 | H8: =G8/F8 -> 0 | J8: 4 | K8: =K7 + 1 -> 4 | L8: =20*K8 -> 80 | M8: =L8 +L8*10% -> 88 | N8: 80 | O8: 88 | P8: =M8-O8 -> 0 | Q8: =P8/O8 -> 0 | S8: 4 | T8: =T7 + 1 -> 4 | U8: =25*T8 -> 100 | V8: =U8 +U8*10% -> 110 | W8: 100 | X8: 110 | Y8: =V8-X8 -> 0 | Z8: =Y8/X8 -> 0 | AB8: 4 | AC8: =AC7 + 1 -> 4 | AD8: =30*AC8 -> 120 | AE8: =AD8 +AD8*10% -> 132 | AF8: 112 | AG8: 123.2 | AH8: =AE8-AG8 -> 8.8 | AI8: =AH8/AG8 -> 0.071428571 | AK8: 4 | AL8: =AL7 + 1 -> 4 | AM8: =40*AL8 -> 160 | AN8: =AM8 +AM8*10% -> 176 | AO8: 120 | AP8: 132 | AQ8: =AN8-AP8 -> 44 | AR8: =AQ8/AP8 -> 0.33333333 | AT8: 4 | AU8: =AU7 + 1 -> 4 | AV8: =54*AU8 -> 216 | AW8: =AV8 +AV8*10% -> 237.6 | AX8: 180 | AY8: 198 | AZ8: =AW8-AY8 -> 39.6 | BA8: =AZ8/AY8 -> 0.2
A9: 5 | B9: =B8 + 1 -> 5 | C9: =18*B9 -> 90 | D9: =C9 +C9*10% -> 99 | E9: 90 | F9: 99 | G9: =D9-F9 -> 0 | H9: =G9/F9 -> 0 | J9: 5 | K9: =K8 + 1 -> 5 | L9: =20*K9 -> 100 | M9: =L9 +L9*10% -> 110 | N9: 100 | O9: 110 | P9: =M9-O9 -> 0 | Q9: =P9/O9 -> 0 | S9: 5 | T9: =T8 + 1 -> 5 | U9: =25*T9 -> 125 | V9: =U9 +U9*10% -> 137.5 | W9: 125 | X9: 137.5 | Y9: =V9-X9 -> 0 | Z9: =Y9/X9 -> 0 | AB9: 5 | AC9: =AC8 + 1 -> 5 | AD9: =30*AC9 -> 150 | AE9: =AD9 +AD9*10% -> 165 | AF9: 140 | AG9: 154 | AH9: =AE9-AG9 -> 11 | AI9: =AH9/AG9 -> 0.071428571 | AK9: 5 | AL9: =AL8 + 1 -> 5 | AM9: =40*AL9 -> 200 | AN9: =AM9 +AM9*10% -> 220 | AO9: 150 | AP9: 165 | AQ9: =AN9-AP9 -> 55 | AR9: =AQ9/AP9 -> 0.33333333 | AT9: 5 | AU9: =AU8 + 1 -> 5 | AV9: =54*AU9 -> 270 | AW9: =AV9 +AV9*10% -> 297 | AX9: 225 | AY9: 247.5 | AZ9: =AW9-AY9 -> 49.5 | BA9: =AZ9/AY9 -> 0.2
A10: 6 | B10: =B9 + 1 -> 6 | C10: =18*B10 -> 108 | D10: =C10 +C10*10% -> 118.8 | E10: 108 | F10: 118.8 | G10: =D10-F10 -> 0 | H10: =G10/F10 -> 0 | J10: 6 | K10: =K9 + 1 -> 6 | L10: =20*K10 -> 120 | M10: =L10 +L10*10% -> 132 | N10: 120 | O10: 132 | P10: =M10-O10 -> 0 | Q10: =P10/O10 -> 0 | S10: 6 | T10: =T9 + 1 -> 6 | U10: =25*T10 -> 150 | V10: =U10 +U10*10% -> 165 | W10: 150 | X10: 165 | Y10: =V10-X10 -> 0 | Z10: =Y10/X10 -> 0 | AB10: 6 | AC10: =AC9 + 1 -> 6 | AD10: =30*AC10 -> 180 | AE10: =AD10 +AD10*10% -> 198 | AF10: 168 | AG10: 184.8 | AH10: =AE10-AG10 -> 13.2 | AI10: =AH10/AG10 -> 0.071428571 | AK10: 6 | AL10: =AL9 + 1 -> 6 | AM10: =40*AL10 -> 240 | AN10: =AM10 +AM10*10% -> 264 | AO10: 180 | AP10: 198 | AQ10: =AN10-AP10 -> 66 | AR10: =AQ10/AP10 -> 0.33333333 | AT10: 6 | AU10: =AU9 + 1 -> 6 | AV10: =54*AU10 -> 324 | AW10: =AV10 +AV10*10% -> 356.4 | AX10: 270 | AY10: 297 | AZ10: =AW10-AY10 -> 59.4 | BA10: =AZ10/AY10 -> 0.2
A11: 7 | B11: =B10 + 1 -> 7 | C11: =18*B11 -> 126 | D11: =C11 +C11*10% -> 138.6 | E11: 126 | F11: 138.6 | G11: =D11-F11 -> 0 | H11: =G11/F11 -> 0 | J11: 7 | K11: =K10 + 1 -> 7 | L11: =20*K11 -> 140 | M11: =L11 +L11*10% -> 154 | N11: 140 | O11: 154 | P11: =M11-O11 -> 0 | Q11: =P11/O11 -> 0 | S11: 7 | T11: =T10 + 1 -> 7 | U11: =25*T11 -> 175 | V11: =U11 +U11*10% -> 192.5 | W11: 175 | X11: 192.5 | Y11: =V11-X11 -> 0 | Z11: =Y11/X11 -> 0 | AB11: 7 | AC11: =AC10 + 1 -> 7 | AD11: =30*AC11 -> 210 | AE11: =AD11 +AD11*10% -> 231 | AF11: 196 | AG11: 215.6 | AH11: =AE11-AG11 -> 15.4 | AI11: =AH11/AG11 -> 0.071428571 | AK11: 7 | AL11: =AL10 + 1 -> 7 | AM11: =40*AL11 -> 280 | AN11: =AM11 +AM11*10% -> 308 | AO11: 210 | AP11: 231 | AQ11: =AN11-AP11 -> 77 | AR11: =AQ11/AP11 -> 0.33333333 | AT11: 7 | AU11: =AU10 + 1 -> 7 | AV11: =54*AU11 -> 378 | AW11: =AV11 +AV11*10% -> 415.8 | AX11: 315 | AY11: 346.5 | AZ11: =AW11-AY11 -> 69.3 | BA11: =AZ11/AY11 -> 0.2
A12: 8 | B12: =B11 + 1 -> 8 | C12: =18*B12 -> 144 | D12: =C12 +C12*10% -> 158.4 | E12: 144 | F12: 158.4 | G12: =D12-F12 -> 0 | H12: =G12/F12 -> 0 | J12: 8 | K12: =K11 + 1 -> 8 | L12: =20*K12 -> 160 | M12: =L12 +L12*10% -> 176 | N12: 160 | O12: 176 | P12: =M12-O12 -> 0 | Q12: =P12/O12 -> 0 | S12: 8 | T12: =T11 + 1 -> 8 | U12: =25*T12 -> 200 | V12: =U12 +U12*10% -> 220 | W12: 200 | X12: 220 | Y12: =V12-X12 -> 0 | Z12: =Y12/X12 -> 0 | AB12: 8 | AC12: =AC11 + 1 -> 8 | AD12: =30*AC12 -> 240 | AE12: =AD12 +AD12*10% -> 264 | AF12: 224 | AG12: 246.4 | AH12: =AE12-AG12 -> 17.6 | AI12: =AH12/AG12 -> 0.071428571 | AK12: 8 | AL12: =AL11 + 1 -> 8 | AM12: =40*AL12 -> 320 | AN12: =AM12 +AM12*10% -> 352 | AO12: 240 | AP12: 264 | AQ12: =AN12-AP12 -> 88 | AR12: =AQ12/AP12 -> 0.33333333 | AT12: 8 | AU12: =AU11 + 1 -> 8 | AV12: =54*AU12 -> 432 | AW12: =AV12 +AV12*10% -> 475.2 | AX12: 360 | AY12: 396 | AZ12: =AW12-AY12 -> 79.2 | BA12: =AZ12/AY12 -> 0.2
A13: 9 | B13: =B12 + 1 -> 9 | C13: =18*B13 -> 162 | D13: =C13 +C13*10% -> 178.2 | E13: 162 | F13: 178.2 | G13: =D13-F13 -> 0 | H13: =G13/F13 -> 0 | J13: 9 | K13: =K12 + 1 -> 9 | L13: =20*K13 -> 180 | M13: =L13 +L13*10% -> 198 | N13: 180 | O13: 198 | P13: =M13-O13 -> 0 | Q13: =P13/O13 -> 0 | S13: 9 | T13: =T12 + 1 -> 9 | U13: =25*T13 -> 225 | V13: =U13 +U13*10% -> 247.5 | W13: 225 | X13: 247.5 | Y13: =V13-X13 -> 0 | Z13: =Y13/X13 -> 0 | AB13: 9 | AC13: =AC12 + 1 -> 9 | AD13: =30*AC13 -> 270 | AE13: =AD13 +AD13*10% -> 297 | AF13: 252 | AG13: 277.2 | AH13: =AE13-AG13 -> 19.8 | AI13: =AH13/AG13 -> 0.071428571 | AK13: 9 | AL13: =AL12 + 1 -> 9 | AM13: =40*AL13 -> 360 | AN13: =AM13 +AM13*10% -> 396 | AO13: 270 | AP13: 297 | AQ13: =AN13-AP13 -> 99 | AR13: =AQ13/AP13 -> 0.33333333 | AT13: 9 | AU13: =AU12 + 1 -> 9 | AV13: =54*AU13 -> 486 | AW13: =AV13 +AV13*10% -> 534.6 | AX13: 405 | AY13: 445.5 | AZ13: =AW13-AY13 -> 89.1 | BA13: =AZ13/AY13 -> 0.2
A14: 10 | B14: =B13 + 1 -> 10 | C14: =18*B14 -> 180 | D14: =C14 +C14*10% -> 198 | E14: 180 | F14: 198 | G14: =D14-F14 -> 0 | H14: =G14/F14 -> 0 | J14: 10 | K14: =K13 + 1 -> 10 | L14: =20*K14 -> 200 | M14: =L14 +L14*10% -> 220 | N14: 200 | O14: 220 | P14: =M14-O14 -> 0 | Q14: =P14/O14 -> 0 | S14: 10 | T14: =T13 + 1 -> 10 | U14: =25*T14 -> 250 | V14: =U14 +U14*10% -> 275 | W14: 250 | X14: 275 | Y14: =V14-X14 -> 0 | Z14: =Y14/X14 -> 0 | AB14: 10 | AC14: =AC13 + 1 -> 10 | AD14: =30*AC14 -> 300 | AE14: =AD14 +AD14*10% -> 330 | AF14: 280 | AG14: 308 | AH14: =AE14-AG14 -> 22 | AI14: =AH14/AG14 -> 0.071428571 | AK14: 10 | AL14: =AL13 + 1 -> 10 | AM14: =40*AL14 -> 400 | AN14: =AM14 +AM14*10% -> 440 | AO14: 300 | AP14: 330 | AQ14: =AN14-AP14 -> 110 | AR14: =AQ14/AP14 -> 0.33333333 | AT14: 10 | AU14: =AU13 + 1 -> 10 | AV14: =54*AU14 -> 540 | AW14: =AV14 +AV14*10% -> 594 | AX14: 450 | AY14: 495 | AZ14: =AW14-AY14 -> 99 | BA14: =AZ14/AY14 -> 0.2
A15: 11 | B15: =B14 + 1 -> 11 | C15: =18*B15 -> 198 | D15: =C15 +C15*10% -> 217.8 | E15: 198 | F15: 217.8 | G15: =D15-F15 -> 0 | H15: =G15/F15 -> 0 | J15: 11 | K15: =K14 + 1 -> 11 | L15: =20*K15 -> 220 | M15: =L15 +L15*10% -> 242 | N15: 220 | O15: 242 | P15: =M15-O15 -> 0 | Q15: =P15/O15 -> 0 | S15: 11 | T15: =T14 + 1 -> 11 | U15: =25*T15 -> 275 | V15: =U15 +U15*10% -> 302.5 | W15: 275 | X15: 302.5 | Y15: =V15-X15 -> 0 | Z15: =Y15/X15 -> 0 | AB15: 11 | AC15: =AC14 + 1 -> 11 | AD15: =30*AC15 -> 330 | AE15: =AD15 +AD15*10% -> 363 | AF15: 308 | AG15: 338.8 | AH15: =AE15-AG15 -> 24.2 | AI15: =AH15/AG15 -> 0.071428571 | AK15: 11 | AL15: =AL14 + 1 -> 11 | AM15: =40*AL15 -> 440 | AN15: =AM15 +AM15*10% -> 484 | AO15: 330 | AP15: 363 | AQ15: =AN15-AP15 -> 121 | AR15: =AQ15/AP15 -> 0.33333333 | AT15: 11 | AU15: =AU14 + 1 -> 11 | AV15: =54*AU15 -> 594 | AW15: =AV15 +AV15*10% -> 653.4 | AX15: 495 | AY15: 544.5 | AZ15: =AW15-AY15 -> 108.9 | BA15: =AZ15/AY15 -> 0.2
A16: 12 | B16: =B15 + 1 -> 12 | C16: =18*B16 -> 216 | D16: =C16 +C16*10% -> 237.6 | E16: 216 | F16: 237.6 | G16: =D16-F16 -> 0 | H16: =G16/F16 -> 0 | J16: 12 | K16: =K15 + 1 -> 12 | L16: =20*K16 -> 240 | M16: =L16 +L16*10% -> 264 | N16: 240 | O16: 264 | P16: =M16-O16 -> 0 | Q16: =P16/O16 -> 0 | S16: 12 | T16: =T15 + 1 -> 12 | U16: =25*T16 -> 300 | V16: =U16 +U16*10% -> 330 | W16: 300 | X16: 330 | Y16: =V16-X16 -> 0 | Z16: =Y16/X16 -> 0 | AB16: 12 | AC16: =AC15 + 1 -> 12 | AD16: =30*AC16 -> 360 | AE16: =AD16 +AD16*10% -> 396 | AF16: 336 | AG16: 369.6 | AH16: =AE16-AG16 -> 26.4 | AI16: =AH16/AG16 -> 0.071428571 | AK16: 12 | AL16: =AL15 + 1 -> 12 | AM16: =40*AL16 -> 480 | AN16: =AM16 +AM16*10% -> 528 | AO16: 360 | AP16: 396 | AQ16: =AN16-AP16 -> 132 | AR16: =AQ16/AP16 -> 0.33333333 | AT16: 12 | AU16: =AU15 + 1 -> 12 | AV16: =54*AU16 -> 648 | AW16: =AV16 +AV16*10% -> 712.8 | AX16: 540 | AY16: 594 | AZ16: =AW16-AY16 -> 118.8 | BA16: =AZ16/AY16 -> 0.2
A17: 13 | B17: =B16 + 1 -> 13 | C17: =18*B17 -> 234 | D17: =C17 +C17*10% -> 257.4 | E17: 234 | F17: 257.4 | G17: =D17-F17 -> 0 | H17: =G17/F17 -> 0 | J17: 13 | K17: =K16 + 1 -> 13 | L17: =20*K17 -> 260 | M17: =L17 +L17*10% -> 286 | N17: 260 | O17: 286 | P17: =M17-O17 -> 0 | Q17: =P17/O17 -> 0 | S17: 13 | T17: =T16 + 1 -> 13 | U17: =25*T17 -> 325 | V17: =U17 +U17*10% -> 357.5 | W17: 325 | X17: 357.5 | Y17: =V17-X17 -> 0 | Z17: =Y17/X17 -> 0 | AB17: 13 | AC17: =AC16 + 1 -> 13 | AD17: =30*AC17 -> 390 | AE17: =AD17 +AD17*10% -> 429 | AF17: 364 | AG17: 400.4 | AH17: =AE17-AG17 -> 28.6 | AI17: =AH17/AG17 -> 0.071428571 | AK17: 13 | AL17: =AL16 + 1 -> 13 | AM17: =40*AL17 -> 520 | AN17: =AM17 +AM17*10% -> 572 | AO17: 390 | AP17: 429 | AQ17: =AN17-AP17 -> 143 | AR17: =AQ17/AP17 -> 0.33333333 | AT17: 13 | AU17: =AU16 + 1 -> 13 | AV17: =54*AU17 -> 702 | AW17: =AV17 +AV17*10% -> 772.2 | AX17: 585 | AY17: 643.5 | AZ17: =AW17-AY17 -> 128.7 | BA17: =AZ17/AY17 -> 0.2
A18: 14 | B18: =B17 + 1 -> 14 | C18: =18*B18 -> 252 | D18: =C18 +C18*10% -> 277.2 | E18: 252 | F18: 277.2 | G18: =D18-F18 -> 0 | H18: =G18/F18 -> 0 | J18: 14 | K18: =K17 + 1 -> 14 | L18: =20*K18 -> 280 | M18: =L18 +L18*10% -> 308 | N18: 280 | O18: 308 | P18: =M18-O18 -> 0 | Q18: =P18/O18 -> 0 | S18: 14 | T18: =T17 + 1 -> 14 | U18: =25*T18 -> 350 | V18: =U18 +U18*10% -> 385 | W18: 350 | X18: 385 | Y18: =V18-X18 -> 0 | Z18: =Y18/X18 -> 0 | AB18: 14 | AC18: =AC17 + 1 -> 14 | AD18: =30*AC18 -> 420 | AE18: =AD18 +AD18*10% -> 462 | AF18: 392 | AG18: 431.2 | AH18: =AE18-AG18 -> 30.8 | AI18: =AH18/AG18 -> 0.071428571 | AK18: 14 | AL18: =AL17 + 1 -> 14 | AM18: =40*AL18 -> 560 | AN18: =AM18 +AM18*10% -> 616 | AO18: 420 | AP18: 462 | AQ18: =AN18-AP18 -> 154 | AR18: =AQ18/AP18 -> 0.33333333 | AT18: 14 | AU18: =AU17 + 1 -> 14 | AV18: =54*AU18 -> 756 | AW18: =AV18 +AV18*10% -> 831.6 | AX18: 630 | AY18: 693 | AZ18: =AW18-AY18 -> 138.6 | BA18: =AZ18/AY18 -> 0.2
A19: 15 | B19: =B18 + 1 -> 15 | C19: =18*B19 -> 270 | D19: =C19 +C19*10% -> 297 | E19: 270 | F19: 297 | G19: =D19-F19 -> 0 | H19: =G19/F19 -> 0 | J19: 15 | K19: =K18 + 1 -> 15 | L19: =20*K19 -> 300 | M19: =L19 +L19*10% -> 330 | N19: 300 | O19: 330 | P19: =M19-O19 -> 0 | Q19: =P19/O19 -> 0 | S19: 15 | T19: =T18 + 1 -> 15 | U19: =25*T19 -> 375 | V19: =U19 +U19*10% -> 412.5 | W19: 375 | X19: 412.5 | Y19: =V19-X19 -> 0 | Z19: =Y19/X19 -> 0 | AB19: 15 | AC19: =AC18 + 1 -> 15 | AD19: =30*AC19 -> 450 | AE19: =AD19 +AD19*10% -> 495 | AF19: 420 | AG19: 462 | AH19: =AE19-AG19 -> 33 | AI19: =AH19/AG19 -> 0.071428571 | AK19: 15 | AL19: =AL18 + 1 -> 15 | AM19: =40*AL19 -> 600 | AN19: =AM19 +AM19*10% -> 660 | AO19: 450 | AP19: 495 | AQ19: =AN19-AP19 -> 165 | AR19: =AQ19/AP19 -> 0.33333333 | AT19: 15 | AU19: =AU18 + 1 -> 15 | AV19: =54*AU19 -> 810 | AW19: =AV19 +AV19*10% -> 891 | AX19: 675 | AY19: 742.5 | AZ19: =AW19-AY19 -> 148.5 | BA19: =AZ19/AY19 -> 0.2
... A54: 50 | B54: =B53 + 1 -> 50 | C54: =18*B54 -> 900 | D54: =C54 +C54*10% -> 990 | E54: 900 | F54: 990 | G54: =D54-F54 -> 0 | H54: =G54/F54 -> 0 | J54: 50 | K54: =K53 + 1 -> 50 | L54: =20*K54 -> 1000 | M54: =L54 +L54*10% -> 1100 | N54: 1000 | O54: 1100 | P54: =M54-O54 -> 0 | Q54: =P54/O54 -> 0 | S54: 50 | T54: =T53 + 1 -> 50 | U54: =25*T54 -> 1250 | V54: =U54 +U54*10% -> 1375 | W54: 1250 | X54: 1375 | Y54: =V54-X54 -> 0 | Z54: =Y54/X54 -> 0 | AB54: 50 | AC54: =AC53 + 1 -> 50 | AD54: =30*AC54 -> 1500 | AE54: =AD54 +AD54*10% -> 1650 | AF54: 1400 | AG54: 1540 | AH54: =AE54-AG54 -> 110 | AI54: =AH54/AG54 -> 0.071428571 | AK54: 50 | AL54: =AL53 + 1 -> 50 | AM54: =40*AL54 -> 2000 | AN54: =AM54 +AM54*10% -> 2200 | AO54: 1500 | AP54: 1650 | AQ54: =AN54-AP54 -> 550 | AR54: =AQ54/AP54 -> 0.33333333 | AT54: 50 | AU54: =AU53 + 1 -> 50 | AV54: =54*AU54 -> 2700 | AW54: =AV54 +AV54*10% -> 2970 | AX54: 2250 | AY54: 2475 | AZ54: =AW54-AY54 -> 495 | BA54: =AZ54/AY54 -> 0.2
A55: AVERAGE DIFFERENCE % | H55: =AVERAGE(H7:H54) -> 0 | J55: AVERAGE DIFFERENCE % | Q55: =AVERAGE(Q7:Q54) -> 0 | S55: AVERAGE DIFFERENCE % | Z55: =AVERAGE(Z7:Z54) -> 0 | AB55: AVERAGE DIFFERENCE % | AI55: =AVERAGE(AI7:AI54) -> 0.071428571 | AK55: AVERAGE DIFFERENCE % | AR55: =AVERAGE(AR7:AR54) -> 0.33333333 | AT55: AVERAGE DIFFERENCE % | BA55: =AVERAGE(BA7:BA54) -> 0.2
A57: WITHIN CITY | J57: WITHIN STATE | S57: WITHIN ZONE | AB57: METRO TO METRO | AK57: REST OF INDIA | AT57: SPECIAL DESTINATION
A58: DOCUMENT CHARGE BY SURFACE | J58: DOCUMENT CHARGE BY SURFACE | S58: DOCUMENT CHARGE BY SURFACE | AB58: NON-DOCUMENT CHARGE BY SURFACE | AK58: DOCUMENT CHARGE BY SURFACE | AT58: DOCUMENT CHARGE BY SURFACE
A59: SR.NO. | B59: KGS | C59: DTDC PREV | D59: TOTAL COST | E59: DTDC CURRENT | F59: TOTAL COST | G59: DIFF. | H59: %DIFF. | J59: SR.NO. | K59: KGS | L59: DTDC PREV | M59: TOTAL COST | N59: DTDC CURRENT | O59: TOTAL COST | P59: DIFF. | Q59: %DIFF. | S59: SR.NO. | T59: KGS | U59: DTDC PREV | V59: TOTAL COST | W59: DTDC CURRENT | X59: TOTAL COST | Y59: DIFF. | Z59: %DIFF. | AB59: SR.NO. | AC59: KGS | AD59: DTDC PREV | AE59: TOTAL COST | AF59: DTDC CURRENT | AG59: TOTAL COST | AH59: DIFF. | AI59: %DIFF. | AK59: SR.NO. | AL59: KGS | AM59: DTDC PREV | AN59: TOTAL COST | AO59: DTDC CURRENT | AP59: TOTAL COST | AQ59: DIFF. | AR59: %DIFF. | AT59: SR.NO. | AU59: KGS | AV59: DTDC PREV | AW59: TOTAL COST | AX59: DTDC CURRENT | AY59: TOTAL COST | AZ59: DIFF. | BA59: %DIFF.
A60: {=_xlfn.SEQUENCE(4)} -> 1 | B60: 0.1 | C60: 15 | D60: =C60 +10%*C60 -> 16.5 | E60: 12.5 | F60: =E60+10%*E60 -> 13.75 | G60: =D60-F60 -> 2.75 | H60: =G60/F60 -> 0.2 | J60: {=_xlfn.SEQUENCE(4)} -> 1 | K60: 0.1 | L60: 16 | M60: =L60 +10%*L60 -> 17.6 | N60: 13.5 | O60: =N60+10%*N60 -> 14.85 | P60: =M60-O60 -> 2.75 | Q60: =P60/O60 -> 0.18518519 | S60: {=_xlfn.SEQUENCE(4)} -> 1 | T60: 0.1 | U60: 20.5 | V60: =U60 +10%*U60 -> 22.55 | W60: 16.5 | X60: =W60+10%*W60 -> 18.15 | Y60: =V60-X60 -> 4.4 | Z60: =Y60/X60 -> 0.24242424 | AB60: {=_xlfn.SEQUENCE(4)} -> 1 | AC60: 0.1 | AD60: 33.5 | AE60: =AD60 +10%*AD60 -> 36.85 | AF60: 26.5 | AG60: =AF60+10%*AF60 -> 29.15 | AH60: =AE60-AG60 -> 7.7 | AI60: =AH60/AG60 -> 0.26415094 | AK60: {=_xlfn.SEQUENCE(4)} -> 1 | AL60: 0.1 | AM60: 36.5 | AN60: =AM60 +10%*AM60 -> 40.15 | AO60: 29 | AP60: =AO60+10%*AO60 -> 31.9 | AQ60: =AN60-AP60 -> 8.25 | AR60: =AQ60/AP60 -> 0.25862069 | AT60: {=_xlfn.SEQUENCE(4)} -> 1 | AU60: 0.1 | AV60: 43 | AW60: =AV60 +10%*AV60 -> 47.3 | AX60: 36.5 | AY60: =AX60+AX60*10% -> 40.15 | AZ60: =AW60-AY60 -> 7.15 | BA60: =AZ60/AY60 -> 0.17808219
A61: 2 | B61: 0.25 | C61: 15.5 | D61: =C61 +10%*C61 -> 17.05 | E61: 13 | F61: =E61+10%*E61 -> 14.3 | G61: =D61-F61 -> 2.75 | H61: =G61/F61 -> 0.19230769 | J61: 2 | K61: 0.25 | L61: 16.5 | M61: =L61 +10%*L61 -> 18.15 | N61: 14 | O61: =N61+10%*N61 -> 15.4 | P61: =M61-O61 -> 2.75 | Q61: =P61/O61 -> 0.17857143 | S61: 2 | T61: 0.25 | U61: 22 | V61: =U61 +10%*U61 -> 24.2 | W61: 18 | X61: =W61+10%*W61 -> 19.8 | Y61: =V61-X61 -> 4.4 | Z61: =Y61/X61 -> 0.22222222 | AB61: 2 | AC61: 0.25 | AD61: 35.5 | AE61: =AD61 +10%*AD61 -> 39.05 | AF61: 28.5 | AG61: =AF61+10%*AF61 -> 31.35 | AH61: =AE61-AG61 -> 7.7 | AI61: =AH61/AG61 -> 0.24561404 | AK61: 2 | AL61: 0.25 | AM61: 39.5 | AN61: =AM61 +10%*AM61 -> 43.45 | AO61: 31.5 | AP61: =AO61+10%*AO61 -> 34.65 | AQ61: =AN61-AP61 -> 8.8 | AR61: =AQ61/AP61 -> 0.25396825 | AT61: 2 | AU61: 0.25 | AV61: 45.5 | AW61: =AV61 +10%*AV61 -> 50.05 | AX61: 38.5 | AY61: =AX61+AX61*10% -> 42.35 | AZ61: =AW61-AY61 -> 7.7 | BA61: =AZ61/AY61 -> 0.18181818
A62: 3 | B62: 0.5 | C62: 16 | D62: =C62 +10%*C62 -> 17.6 | E62: 13.5 | F62: =E62+10%*E62 -> 14.85 | G62: =D62-F62 -> 2.75 | H62: =G62/F62 -> 0.18518519 | J62: 3 | K62: 0.5 | L62: 17 | M62: =L62 +10%*L62 -> 18.7 | N62: 14.5 | O62: =N62+10%*N62 -> 15.95 | P62: =M62-O62 -> 2.75 | Q62: =P62/O62 -> 0.17241379 | S62: 3 | T62: 0.5 | U62: 23 | V62: =U62 +10%*U62 -> 25.3 | W62: 19 | X62: =W62+10%*W62 -> 20.9 | Y62: =V62-X62 -> 4.4 | Z62: =Y62/X62 -> 0.21052632 | AB62: 3 | AC62: 0.5 | AD62: 45 | AE62: =AD62 +10%*AD62 -> 49.5 | AF62: 41.5 | AG62: =AF62+10%*AF62 -> 45.65 | AH62: =AE62-AG62 -> 3.85 | AI62: =AH62/AG62 -> 0.084337349 | AK62: 3 | AL62: 0.5 | AM62: 50 | AN62: =AM62 +10%*AM62 -> 55 | AO62: 44.5 | AP62: =AO62+10%*AO62 -> 48.95 | AQ62: =AN62-AP62 -> 6.05 | AR62: =AQ62/AP62 -> 0.12359551 | AT62: 3 | AU62: 0.5 | AV62: 65 | AW62: =AV62 +10%*AV62 -> 71.5 | AX62: 63 | AY62: =AX62+AX62*10% -> 69.3 | AZ62: =AW62-AY62 -> 2.2 | BA62: =AZ62/AY62 -> 0.031746032
A63: 4 | B63: 1 | C63: =C62+9.5 -> 25.5 | D63: =C63 +10%*C63 -> 28.05 | E63: =E62 + 7.5 -> 21 | F63: =E63+10%*E63 -> 23.1 | G63: =D63-F63 -> 4.95 | H63: =G63/F63 -> 0.21428571 | J63: 4 | K63: 1 | L63: =L62 + 10.5 -> 27.5 | M63: =L63 +10%*L63 -> 30.25 | N63: =N62+8.5 -> 23 | O63: =N63+10%*N63 -> 25.3 | P63: =M63-O63 -> 4.95 | Q63: =P63/O63 -> 0.19565217 | S63: 4 | T63: 1 | U63: =U62 +17 -> 40 | V63: =U63 +10%*U63 -> 44 | W63: =W62 +14.5 -> 33.5 | X63: =W63+10%*W63 -> 36.85 | Y63: =V63-X63 -> 7.15 | Z63: =Y63/X63 -> 0.19402985 | AB63: 4 | AC63: 1 | AD63: =AD62+30 -> 75 | AE63: =AD63 +10%*AD63 -> 82.5 | AF63: =AF62+35.5 -> 77 | AG63: =AF63+10%*AF63 -> 84.7 | AH63: =AE63-AG63 -> -2.2 | AI63: =AH63/AG63 -> -0.025974026 | AK63: 4 | AL63: 1 | AM63: =AM62+35 -> 85 | AN63: =AM63 +10%*AM63 -> 93.5 | AO63: =AO62 + 38 -> 82.5 | AP63: =AO63+10%*AO63 -> 90.75 | AQ63: =AN63-AP63 -> 2.75 | AR63: =AQ63/AP63 -> 0.03030303 | AT63: 4 | AU63: 1 | AV63: =AV62+60 -> 125 | AW63: =AV63 +10%*AV63 -> 137.5 | AX63: =AX62+55.5 -> 118.5 | AY63: =AX63+AX63*10% -> 130.35 | AZ63: =AW63-AY63 -> 7.15 | BA63: =AZ63/AY63 -> 0.054852321
A64: AVERAGE DIFFERENCE % | H64: =AVERAGE(H60:H63) -> 0.19794465 | J64: AVERAGE DIFFERENCE % | Q64: =AVERAGE(Q60:Q63) -> 0.18295565 | S64: AVERAGE DIFFERENCE % | Z64: =AVERAGE(Z60:Z63) -> 0.21730066 | AB64: AVERAGE DIFFERENCE % | AI64: =AVERAGE(AI60:AI63) -> 0.14203208 | AK64: AVERAGE DIFFERENCE % | AR64: =AVERAGE(AR60:AR63) -> 0.16662187 | AT64: AVERAGE DIFFERENCE % | BA64: =AVERAGE(BA60:BA63) -> 0.11162468

Sheet SPECIALDESTINATION
A1: SR.NO. | B1: KGS | C1: PROFESSIONAL PER KG | D1: ANJANI COURIERS PER KG | E1: DTDC PER KG | F1: SHREE MARUTI COURIER SERVICE PER KG | G1: ITHINK LOGISTICS DELHIVERY | H1: ITHINK LOGISTICS BLUEDART | I1: ITHINK LOGISTICS EKART | J1: ITHINK LOGISTICS SHADOWFAX | K1: ITHINK LOGISTICS AMAZON | L1: ITHINK LOGISTICS DTDC | M1: ITHINK LOGISTICS XPRESSBEES | N1: PROFESSIONAL COURIER SERVICE | O1: DTDC | P1: SHREE MARUTI COURIER SERVICE | Q1: ANJANI COURIER SERVICE | R1: HIGHEST COST | S1: LOWEST COST | T1: DIFFERENCE | U1: CHEAPEST COURIER | V1: EXPENSIVE COURIER
G2: FWD ADDN 0.5KG | H2: FWD ADDN 0.5KG | I2: FWD ADDN 0.5KG | J2: FWD ADDN 0.5KG | K2: FWD ADDN 0.5KG | L2: FWD ADDN 0.5KG | M2: FWD ADDN 0.5KG | N2: FUEL SURCHARGE | O2: FUEL SURCHARGE | P2: FUEL SURCHARGE | Q2: FUEL SURCHARGE
C3: 70 | D3: 180 | E3: 45 | F3: 60 | G3: 57 | H3: 58.98 | I3: 49.5 | J3: 43.25 | K3: 45.75 | L3: 54.44 | M3: 50.5 | N3: 0.1 | O3: 0.1 | P3: 0.1 | Q3: 0.35
A4: {=_xlfn.SEQUENCE(50)} -> 1 | B4: 1 | C4: =B4*$C$3 -> 70 | D4: =B4*$D$3 -> 180 | E4: =$E$3*B6 -> 135 | F4: =B4*$F$3 -> 60 | G4: =63.25+$G$3 -> 120.25 | H4: =61.65+$H$3 -> 120.63 | I4: =53.25+$I$3 -> 102.75 | J4: =47+$J$3 -> 90.25 | K4: =50.75+$K$3 -> 96.5 | L4: =45.75+$L$3 -> 100.19 | M4: =54.44+$M$3 -> 104.94 | N4: =C4 + $N$3*C4 -> 77 | O4: =E4 + $O$3*E4 -> 148.5 | P4: =F4 + $P$3*F4 -> 66 | Q4: =D4 + $Q$3*D4 -> 243 | R4: =MAX(G4:Q4) -> 243 | S4: =MIN(G4:Q4) -> 66 | T4: =R4 - S4 -> 177 | U4: =INDEX($C$1:$M$1, MATCH(MIN(C6:M6), C6:M6, 0)) -> DTDC PER KG | V4: =INDEX($G$1:$Q$1, MATCH(MAX(G4:Q4), G4:Q4,0)) -> ANJANI COURIER SERVICE
